[2025-07-05T22:39:56.518+0000] {local_task_job_runner.py:120} INFO - ::group::Pre task execution logs
[2025-07-05T22:39:56.543+0000] {taskinstance.py:2076} INFO - Dependencies all met for dep_context=non-requeueable deps ti=<TaskInstance: weekly_model_retraining.retrain_model manual__2025-07-05T22:39:53.497777+00:00 [queued]>
[2025-07-05T22:39:56.549+0000] {taskinstance.py:2076} INFO - Dependencies all met for dep_context=requeueable deps ti=<TaskInstance: weekly_model_retraining.retrain_model manual__2025-07-05T22:39:53.497777+00:00 [queued]>
[2025-07-05T22:39:56.549+0000] {taskinstance.py:2306} INFO - Starting attempt 1 of 2
[2025-07-05T22:39:56.557+0000] {taskinstance.py:2330} INFO - Executing <Task(PythonOperator): retrain_model> on 2025-07-05 22:39:53.497777+00:00
[2025-07-05T22:39:56.566+0000] {logging_mixin.py:188} WARNING - /home/***/.local/lib/python3.12/site-packages/***/task/task_runner/standard_task_runner.py:61 DeprecationWarning: This process (pid=217) is multi-threaded, use of fork() may lead to deadlocks in the child.
[2025-07-05T22:39:56.567+0000] {standard_task_runner.py:63} INFO - Started process 226 to run task
[2025-07-05T22:39:56.567+0000] {standard_task_runner.py:90} INFO - Running: ['***', 'tasks', 'run', 'weekly_model_retraining', 'retrain_model', 'manual__2025-07-05T22:39:53.497777+00:00', '--job-id', '78', '--raw', '--subdir', 'DAGS_FOLDER/retraining_dag.py', '--cfg-path', '/tmp/tmpabn_7lpg']
[2025-07-05T22:39:56.569+0000] {standard_task_runner.py:91} INFO - Job 78: Subtask retrain_model
[2025-07-05T22:39:56.579+0000] {logging_mixin.py:188} WARNING - /home/***/.local/lib/python3.12/site-packages/***/settings.py:195 DeprecationWarning: The sql_alchemy_conn option in [core] has been moved to the sql_alchemy_conn option in [database] - the old setting has been used, but please update your config.
[2025-07-05T22:39:56.602+0000] {task_command.py:426} INFO - Running <TaskInstance: weekly_model_retraining.retrain_model manual__2025-07-05T22:39:53.497777+00:00 [running]> on host acd4cbd137b8
[2025-07-05T22:39:56.691+0000] {taskinstance.py:2648} INFO - Exporting env vars: AIRFLOW_CTX_DAG_OWNER='rajat' AIRFLOW_CTX_DAG_ID='weekly_model_retraining' AIRFLOW_CTX_TASK_ID='retrain_model' AIRFLOW_CTX_EXECUTION_DATE='2025-07-05T22:39:53.497777+00:00' AIRFLOW_CTX_TRY_NUMBER='1' AIRFLOW_CTX_DAG_RUN_ID='manual__2025-07-05T22:39:53.497777+00:00'
[2025-07-05T22:39:56.691+0000] {taskinstance.py:430} INFO - ::endgroup::
[2025-07-05T22:39:56.717+0000] {logging_mixin.py:188} INFO - [INFO] Found latest timestamp: 2025-07-04-15
[2025-07-05T22:39:56.717+0000] {logging_mixin.py:188} INFO - [INFO] Starting model training...
[2025-07-05T22:39:57.098+0000] {connectionpool.py:874} WARNING - Retrying (Retry(total=6, connect=6, read=7, redirect=7, status=7)) after connection broken by 'NameResolutionError("<urllib3.connection.HTTPConnection object at 0x796898e27320>: Failed to resolve 'mlflow-server' ([Errno -2] Name or service not known)")': /api/2.0/mlflow/experiments/get-by-name?experiment_name=anomaly_detection_github
[2025-07-05T22:40:01.383+0000] {connectionpool.py:874} WARNING - Retrying (Retry(total=5, connect=5, read=7, redirect=7, status=7)) after connection broken by 'NameResolutionError("<urllib3.connection.HTTPConnection object at 0x796898cbaf90>: Failed to resolve 'mlflow-server' ([Errno -2] Name or service not known)")': /api/2.0/mlflow/experiments/get-by-name?experiment_name=anomaly_detection_github
[2025-07-05T22:40:09.516+0000] {connectionpool.py:874} WARNING - Retrying (Retry(total=4, connect=4, read=7, redirect=7, status=7)) after connection broken by 'NameResolutionError("<urllib3.connection.HTTPConnection object at 0x796898cba210>: Failed to resolve 'mlflow-server' ([Errno -2] Name or service not known)")': /api/2.0/mlflow/experiments/get-by-name?experiment_name=anomaly_detection_github
[2025-07-05T22:40:26.184+0000] {connectionpool.py:874} WARNING - Retrying (Retry(total=3, connect=3, read=7, redirect=7, status=7)) after connection broken by 'NameResolutionError("<urllib3.connection.HTTPConnection object at 0x796898734f80>: Failed to resolve 'mlflow-server' ([Errno -2] Name or service not known)")': /api/2.0/mlflow/experiments/get-by-name?experiment_name=anomaly_detection_github
[2025-07-05T22:40:59.003+0000] {connectionpool.py:874} WARNING - Retrying (Retry(total=2, connect=2, read=7, redirect=7, status=7)) after connection broken by 'NameResolutionError("<urllib3.connection.HTTPConnection object at 0x796898735460>: Failed to resolve 'mlflow-server' ([Errno -2] Name or service not known)")': /api/2.0/mlflow/experiments/get-by-name?experiment_name=anomaly_detection_github
[2025-07-05T22:41:33.359+0000] {local_task_job_runner.py:124} ERROR - Received SIGTERM. Terminating subprocesses
[2025-07-05T22:41:33.380+0000] {process_utils.py:132} INFO - Sending 15 to group 226. PIDs of all processes in the group: [226]
[2025-07-05T22:41:33.384+0000] {process_utils.py:87} INFO - Sending the signal 15 to group 226
[2025-07-05T22:41:33.390+0000] {taskinstance.py:2611} ERROR - Received SIGTERM. Terminating subprocesses.
[2025-07-05T22:41:33.390+0000] {taskinstance.py:441} INFO - ::group::Post task execution logs
[2025-07-05T22:41:33.471+0000] {taskinstance.py:2905} ERROR - Task failed with exception
Traceback (most recent call last):
  File "/home/airflow/.local/lib/python3.12/site-packages/urllib3/connection.py", line 198, in _new_conn
    sock = connection.create_connection(
           ^^^^^^^^^^^^^^^^^^^^^^^^^^^^^
  File "/home/airflow/.local/lib/python3.12/site-packages/urllib3/util/connection.py", line 60, in create_connection
    for res in socket.getaddrinfo(host, port, family, socket.SOCK_STREAM):
               ^^^^^^^^^^^^^^^^^^^^^^^^^^^^^^^^^^^^^^^^^^^^^^^^^^^^^^^^^^
  File "/usr/local/lib/python3.12/socket.py", line 963, in getaddrinfo
    for res in _socket.getaddrinfo(host, port, family, type, proto, flags):
               ^^^^^^^^^^^^^^^^^^^^^^^^^^^^^^^^^^^^^^^^^^^^^^^^^^^^^^^^^^^
socket.gaierror: [Errno -2] Name or service not known

The above exception was the direct cause of the following exception:

Traceback (most recent call last):
  File "/home/airflow/.local/lib/python3.12/site-packages/urllib3/connectionpool.py", line 793, in urlopen
    response = self._make_request(
               ^^^^^^^^^^^^^^^^^^^
  File "/home/airflow/.local/lib/python3.12/site-packages/urllib3/connectionpool.py", line 496, in _make_request
    conn.request(
  File "/home/airflow/.local/lib/python3.12/site-packages/urllib3/connection.py", line 400, in request
    self.endheaders()
  File "/usr/local/lib/python3.12/http/client.py", line 1331, in endheaders
    self._send_output(message_body, encode_chunked=encode_chunked)
  File "/usr/local/lib/python3.12/http/client.py", line 1091, in _send_output
    self.send(msg)
  File "/usr/local/lib/python3.12/http/client.py", line 1035, in send
    self.connect()
  File "/home/airflow/.local/lib/python3.12/site-packages/urllib3/connection.py", line 238, in connect
    self.sock = self._new_conn()
                ^^^^^^^^^^^^^^^^
  File "/home/airflow/.local/lib/python3.12/site-packages/urllib3/connection.py", line 205, in _new_conn
    raise NameResolutionError(self.host, self, e) from e
urllib3.exceptions.NameResolutionError: <urllib3.connection.HTTPConnection object at 0x796898735af0>: Failed to resolve 'mlflow-server' ([Errno -2] Name or service not known)

During handling of the above exception, another exception occurred:

Traceback (most recent call last):
  File "/home/airflow/.local/lib/python3.12/site-packages/airflow/models/taskinstance.py", line 465, in _execute_task
    result = _execute_callable(context=context, **execute_callable_kwargs)
             ^^^^^^^^^^^^^^^^^^^^^^^^^^^^^^^^^^^^^^^^^^^^^^^^^^^^^^^^^^^^^
  File "/home/airflow/.local/lib/python3.12/site-packages/airflow/models/taskinstance.py", line 432, in _execute_callable
    return execute_callable(context=context, **execute_callable_kwargs)
           ^^^^^^^^^^^^^^^^^^^^^^^^^^^^^^^^^^^^^^^^^^^^^^^^^^^^^^^^^^^^
  File "/home/airflow/.local/lib/python3.12/site-packages/airflow/models/baseoperator.py", line 400, in wrapper
    return func(self, *args, **kwargs)
           ^^^^^^^^^^^^^^^^^^^^^^^^^^^
  File "/home/airflow/.local/lib/python3.12/site-packages/airflow/operators/python.py", line 235, in execute
    return_value = self.execute_callable()
                   ^^^^^^^^^^^^^^^^^^^^^^^
  File "/home/airflow/.local/lib/python3.12/site-packages/airflow/operators/python.py", line 252, in execute_callable
    return self.python_callable(*self.op_args, **self.op_kwargs)
           ^^^^^^^^^^^^^^^^^^^^^^^^^^^^^^^^^^^^^^^^^^^^^^^^^^^^^
  File "/opt/airflow/github_pipeline/train_model.py", line 100, in main
    run_training(latest_ts)
  File "/opt/airflow/github_pipeline/train_model.py", line 45, in run_training
    mlflow.set_experiment(experiment_name)
  File "/home/airflow/.local/lib/python3.12/site-packages/mlflow/tracking/fluent.py", line 183, in set_experiment
    experiment = client.get_experiment_by_name(experiment_name)
                 ^^^^^^^^^^^^^^^^^^^^^^^^^^^^^^^^^^^^^^^^^^^^^^
  File "/home/airflow/.local/lib/python3.12/site-packages/mlflow/tracking/_tracking_service/client.py", line 258, in get_experiment_by_name
    return self.store.get_experiment_by_name(name)
           ^^^^^^^^^^^^^^^^^^^^^^^^^^^^^^^^^^^^^^^
  File "/home/airflow/.local/lib/python3.12/site-packages/mlflow/store/tracking/rest_store.py", line 869, in get_experiment_by_name
    response_proto = self._call_endpoint(GetExperimentByName, req_body)
                     ^^^^^^^^^^^^^^^^^^^^^^^^^^^^^^^^^^^^^^^^^^^^^^^^^^
  File "/home/airflow/.local/lib/python3.12/site-packages/mlflow/store/tracking/rest_store.py", line 135, in _call_endpoint
    return call_endpoint(
           ^^^^^^^^^^^^^^
  File "/home/airflow/.local/lib/python3.12/site-packages/mlflow/utils/rest_utils.py", line 585, in call_endpoint
    response = http_request(**call_kwargs)
               ^^^^^^^^^^^^^^^^^^^^^^^^^^^
  File "/home/airflow/.local/lib/python3.12/site-packages/mlflow/utils/rest_utils.py", line 229, in http_request
    return _get_http_response_with_retries(
           ^^^^^^^^^^^^^^^^^^^^^^^^^^^^^^^^
  File "/home/airflow/.local/lib/python3.12/site-packages/mlflow/utils/request_utils.py", line 237, in _get_http_response_with_retries
    return session.request(method, url, allow_redirects=allow_redirects, **kwargs)
           ^^^^^^^^^^^^^^^^^^^^^^^^^^^^^^^^^^^^^^^^^^^^^^^^^^^^^^^^^^^^^^^^^^^^^^^
  File "/home/airflow/.local/lib/python3.12/site-packages/requests/sessions.py", line 589, in request
    resp = self.send(prep, **send_kwargs)
           ^^^^^^^^^^^^^^^^^^^^^^^^^^^^^^
  File "/home/airflow/.local/lib/python3.12/site-packages/requests/sessions.py", line 703, in send
    r = adapter.send(request, **kwargs)
        ^^^^^^^^^^^^^^^^^^^^^^^^^^^^^^^
  File "/home/airflow/.local/lib/python3.12/site-packages/requests/adapters.py", line 667, in send
    resp = conn.urlopen(
           ^^^^^^^^^^^^^
  File "/home/airflow/.local/lib/python3.12/site-packages/urllib3/connectionpool.py", line 877, in urlopen
    return self.urlopen(
           ^^^^^^^^^^^^^
  File "/home/airflow/.local/lib/python3.12/site-packages/urllib3/connectionpool.py", line 877, in urlopen
    return self.urlopen(
           ^^^^^^^^^^^^^
  File "/home/airflow/.local/lib/python3.12/site-packages/urllib3/connectionpool.py", line 877, in urlopen
    return self.urlopen(
           ^^^^^^^^^^^^^
  [Previous line repeated 2 more times]
  File "/home/airflow/.local/lib/python3.12/site-packages/urllib3/connectionpool.py", line 850, in urlopen
    retries.sleep()
  File "/home/airflow/.local/lib/python3.12/site-packages/urllib3/util/retry.py", line 359, in sleep
    self._sleep_backoff()
  File "/home/airflow/.local/lib/python3.12/site-packages/urllib3/util/retry.py", line 343, in _sleep_backoff
    time.sleep(backoff)
  File "/home/airflow/.local/lib/python3.12/site-packages/airflow/models/taskinstance.py", line 2613, in signal_handler
    raise AirflowTaskTerminated("Task received SIGTERM signal")
airflow.exceptions.AirflowTaskTerminated: Task received SIGTERM signal
[2025-07-05T22:41:33.782+0000] {taskinstance.py:1206} INFO - Marking task as UP_FOR_RETRY. dag_id=weekly_model_retraining, task_id=retrain_model, run_id=manual__2025-07-05T22:39:53.497777+00:00, execution_date=20250705T223953, start_date=20250705T223956, end_date=20250705T224133
[2025-07-05T22:41:33.957+0000] {process_utils.py:80} INFO - Process psutil.Process(pid=226, status='terminated', exitcode=2, started='22:39:56') (226) terminated with exit code 2
[2025-07-05T22:41:33.957+0000] {local_task_job_runner.py:240} INFO - Task exited with return code 143
[2025-07-05T22:41:34.002+0000] {taskinstance.py:3498} INFO - 0 downstream tasks scheduled from follow-on schedule check
[2025-07-05T22:41:36.264+0000] {local_task_job_runner.py:124} ERROR - Received SIGTERM. Terminating subprocesses
[2025-07-05T22:41:36.264+0000] {local_task_job_runner.py:240} INFO - Task exited with return code 143
