[2025-07-09T21:06:15.364+0000] {local_task_job_runner.py:120} INFO - ::group::Pre task execution logs
[2025-07-09T21:06:15.394+0000] {taskinstance.py:2076} INFO - Dependencies all met for dep_context=non-requeueable deps ti=<TaskInstance: weekly_model_retraining.retrain_model manual__2025-07-09T21:06:10.090987+00:00 [queued]>
[2025-07-09T21:06:15.400+0000] {taskinstance.py:2076} INFO - Dependencies all met for dep_context=requeueable deps ti=<TaskInstance: weekly_model_retraining.retrain_model manual__2025-07-09T21:06:10.090987+00:00 [queued]>
[2025-07-09T21:06:15.400+0000] {taskinstance.py:2306} INFO - Starting attempt 1 of 2
[2025-07-09T21:06:15.410+0000] {taskinstance.py:2330} INFO - Executing <Task(PythonOperator): retrain_model> on 2025-07-09 21:06:10.090987+00:00
[2025-07-09T21:06:15.421+0000] {logging_mixin.py:188} WARNING - /home/***/.local/lib/python3.12/site-packages/***/task/task_runner/standard_task_runner.py:61 DeprecationWarning: This process (pid=204) is multi-threaded, use of fork() may lead to deadlocks in the child.
[2025-07-09T21:06:15.422+0000] {standard_task_runner.py:63} INFO - Started process 208 to run task
[2025-07-09T21:06:15.420+0000] {standard_task_runner.py:90} INFO - Running: ['***', 'tasks', 'run', 'weekly_model_retraining', 'retrain_model', 'manual__2025-07-09T21:06:10.090987+00:00', '--job-id', '89', '--raw', '--subdir', 'DAGS_FOLDER/retraining_dag.py', '--cfg-path', '/tmp/tmpdg101_8n']
[2025-07-09T21:06:15.423+0000] {standard_task_runner.py:91} INFO - Job 89: Subtask retrain_model
[2025-07-09T21:06:15.433+0000] {logging_mixin.py:188} WARNING - /home/***/.local/lib/python3.12/site-packages/***/settings.py:195 DeprecationWarning: The sql_alchemy_conn option in [core] has been moved to the sql_alchemy_conn option in [database] - the old setting has been used, but please update your config.
[2025-07-09T21:06:15.468+0000] {task_command.py:426} INFO - Running <TaskInstance: weekly_model_retraining.retrain_model manual__2025-07-09T21:06:10.090987+00:00 [running]> on host 7018af894e0c
[2025-07-09T21:06:15.536+0000] {taskinstance.py:2648} INFO - Exporting env vars: AIRFLOW_CTX_DAG_OWNER='rajat' AIRFLOW_CTX_DAG_ID='weekly_model_retraining' AIRFLOW_CTX_TASK_ID='retrain_model' AIRFLOW_CTX_EXECUTION_DATE='2025-07-09T21:06:10.090987+00:00' AIRFLOW_CTX_TRY_NUMBER='1' AIRFLOW_CTX_DAG_RUN_ID='manual__2025-07-09T21:06:10.090987+00:00'
[2025-07-09T21:06:15.537+0000] {taskinstance.py:430} INFO - ::endgroup::
[2025-07-09T21:06:15.581+0000] {credentials.py:567} INFO - Found credentials in environment variables.
[2025-07-09T21:06:16.091+0000] {logging_mixin.py:188} INFO - [INFO] Searching for files on S3...
[2025-07-09T21:06:16.091+0000] {logging_mixin.py:188} INFO - [INFO] Found latest timestamp: 2025-07-08-15
[2025-07-09T21:06:16.091+0000] {logging_mixin.py:188} INFO - [INFO] Starting model training...
[2025-07-09T21:06:16.187+0000] {credentials.py:567} INFO - Found credentials in environment variables.
[2025-07-09T21:06:17.849+0000] {logging_mixin.py:188} WARNING - 2025/07/09 21:06:17 WARNING mlflow.utils.git_utils: Failed to import Git (the Git executable is probably not on your PATH), so Git SHA is not available. Error: Failed to initialize: Bad git executable.
The git executable must be specified in one of the following ways:
    - be included in your $PATH
    - be set via $GIT_PYTHON_GIT_EXECUTABLE
    - explicitly set via git.refresh(<full-path-to-git-executable>)

All git commands will error until this is rectified.

This initial message can be silenced or aggravated in the future by setting the
$GIT_PYTHON_REFRESH environment variable. Use one of the following values:
    - quiet|q|silence|s|silent|none|n|0: for no message or exception
    - warn|w|warning|log|l|1: for a warning message (logging level CRITICAL, displayed by default)
    - error|e|exception|raise|r|2: for a raised exception

Example:
    export GIT_PYTHON_REFRESH=quiet
[2025-07-09T21:06:18.824+0000] {logging_mixin.py:188} INFO - üèÉ View run rebellious-moth-897 at: http://mlflow-server:5000/#/experiments/1/runs/cad1c043ccc34237933ecf7eeb93c5dd
[2025-07-09T21:06:18.825+0000] {logging_mixin.py:188} INFO - üß™ View experiment at: http://mlflow-server:5000/#/experiments/1
[2025-07-09T21:06:18.837+0000] {taskinstance.py:441} INFO - ::group::Post task execution logs
[2025-07-09T21:06:18.837+0000] {taskinstance.py:2905} ERROR - Task failed with exception
Traceback (most recent call last):
  File "/home/airflow/.local/lib/python3.12/site-packages/airflow/models/taskinstance.py", line 465, in _execute_task
    result = _execute_callable(context=context, **execute_callable_kwargs)
             ^^^^^^^^^^^^^^^^^^^^^^^^^^^^^^^^^^^^^^^^^^^^^^^^^^^^^^^^^^^^^
  File "/home/airflow/.local/lib/python3.12/site-packages/airflow/models/taskinstance.py", line 432, in _execute_callable
    return execute_callable(context=context, **execute_callable_kwargs)
           ^^^^^^^^^^^^^^^^^^^^^^^^^^^^^^^^^^^^^^^^^^^^^^^^^^^^^^^^^^^^
  File "/home/airflow/.local/lib/python3.12/site-packages/airflow/models/baseoperator.py", line 400, in wrapper
    return func(self, *args, **kwargs)
           ^^^^^^^^^^^^^^^^^^^^^^^^^^^
  File "/home/airflow/.local/lib/python3.12/site-packages/airflow/operators/python.py", line 235, in execute
    return_value = self.execute_callable()
                   ^^^^^^^^^^^^^^^^^^^^^^^
  File "/home/airflow/.local/lib/python3.12/site-packages/airflow/operators/python.py", line 252, in execute_callable
    return self.python_callable(*self.op_args, **self.op_kwargs)
           ^^^^^^^^^^^^^^^^^^^^^^^^^^^^^^^^^^^^^^^^^^^^^^^^^^^^^
  File "/opt/airflow/github_pipeline/train_model.py", line 158, in main
    run_training(latest_ts)
  File "/opt/airflow/github_pipeline/train_model.py", line 87, in run_training
    save_pickle((scaler, model), model_file)
  File "/opt/airflow/github_pipeline/utils/aws_utils.py", line 51, in save_pickle
    fs.put(tmp.name, get_s3_path(f"models/{relative_path}"))
  File "/home/airflow/.local/lib/python3.12/site-packages/fsspec/asyn.py", line 118, in wrapper
    return sync(self.loop, func, *args, **kwargs)
                ^^^^^^^^^
  File "/home/airflow/.local/lib/python3.12/site-packages/fsspec/asyn.py", line 340, in loop
    raise RuntimeError("This class is not fork-safe")
RuntimeError: This class is not fork-safe
[2025-07-09T21:06:18.850+0000] {taskinstance.py:1206} INFO - Marking task as UP_FOR_RETRY. dag_id=weekly_model_retraining, task_id=retrain_model, run_id=manual__2025-07-09T21:06:10.090987+00:00, execution_date=20250709T210610, start_date=20250709T210615, end_date=20250709T210618
[2025-07-09T21:06:18.872+0000] {standard_task_runner.py:110} ERROR - Failed to execute job 89 for task retrain_model (This class is not fork-safe; 208)
[2025-07-09T21:06:18.897+0000] {local_task_job_runner.py:240} INFO - Task exited with return code 1
[2025-07-09T21:06:18.911+0000] {taskinstance.py:3498} INFO - 0 downstream tasks scheduled from follow-on schedule check
[2025-07-09T21:06:18.912+0000] {local_task_job_runner.py:222} INFO - ::endgroup::
