[2025-07-09T18:07:14.181+0000] {task_context_logger.py:104} ERROR - Executor reports task instance <TaskInstance: daily_monitoring_dag.run_drift_monitoring scheduled__2025-07-08T00:00:00+00:00 [queued]> finished (failed) although the task says it's queued. (Info: None) Was the task killed externally?
