[2025-07-09T20:16:13.208+0000] {local_task_job_runner.py:120} INFO - ::group::Pre task execution logs
[2025-07-09T20:16:13.227+0000] {taskinstance.py:2076} INFO - Dependencies all met for dep_context=non-requeueable deps ti=<TaskInstance: daily_monitoring_dag.run_drift_monitoring manual__2025-07-09T20:16:08.855380+00:00 [queued]>
[2025-07-09T20:16:13.233+0000] {taskinstance.py:2076} INFO - Dependencies all met for dep_context=requeueable deps ti=<TaskInstance: daily_monitoring_dag.run_drift_monitoring manual__2025-07-09T20:16:08.855380+00:00 [queued]>
[2025-07-09T20:16:13.233+0000] {taskinstance.py:2306} INFO - Starting attempt 1 of 2
[2025-07-09T20:16:13.242+0000] {taskinstance.py:2330} INFO - Executing <Task(PythonOperator): run_drift_monitoring> on 2025-07-09 20:16:08.855380+00:00
[2025-07-09T20:16:13.253+0000] {logging_mixin.py:188} WARNING - /home/***/.local/lib/python3.12/site-packages/***/task/task_runner/standard_task_runner.py:61 DeprecationWarning: This process (pid=328) is multi-threaded, use of fork() may lead to deadlocks in the child.
[2025-07-09T20:16:13.254+0000] {standard_task_runner.py:63} INFO - Started process 332 to run task
[2025-07-09T20:16:13.253+0000] {standard_task_runner.py:90} INFO - Running: ['***', 'tasks', 'run', 'daily_monitoring_dag', 'run_drift_monitoring', 'manual__2025-07-09T20:16:08.855380+00:00', '--job-id', '58', '--raw', '--subdir', 'DAGS_FOLDER/daily_monitoring_dag.py', '--cfg-path', '/tmp/tmp8wfchsa5']
[2025-07-09T20:16:13.258+0000] {standard_task_runner.py:91} INFO - Job 58: Subtask run_drift_monitoring
[2025-07-09T20:16:13.269+0000] {logging_mixin.py:188} WARNING - /home/***/.local/lib/python3.12/site-packages/***/settings.py:195 DeprecationWarning: The sql_alchemy_conn option in [core] has been moved to the sql_alchemy_conn option in [database] - the old setting has been used, but please update your config.
[2025-07-09T20:16:13.291+0000] {task_command.py:426} INFO - Running <TaskInstance: daily_monitoring_dag.run_drift_monitoring manual__2025-07-09T20:16:08.855380+00:00 [running]> on host 49b9a4a3b242
[2025-07-09T20:16:13.373+0000] {taskinstance.py:2648} INFO - Exporting env vars: AIRFLOW_CTX_DAG_OWNER='rajat' AIRFLOW_CTX_DAG_ID='daily_monitoring_dag' AIRFLOW_CTX_TASK_ID='run_drift_monitoring' AIRFLOW_CTX_EXECUTION_DATE='2025-07-09T20:16:08.855380+00:00' AIRFLOW_CTX_TRY_NUMBER='1' AIRFLOW_CTX_DAG_RUN_ID='manual__2025-07-09T20:16:08.855380+00:00'
[2025-07-09T20:16:13.374+0000] {taskinstance.py:430} INFO - ::endgroup::
[2025-07-09T20:16:13.395+0000] {logging_mixin.py:188} INFO - [INFO] Monitoring drift: ref=2025-07-04-15, current=2025-07-05-15
[2025-07-09T20:16:13.395+0000] {taskinstance.py:441} INFO - ::group::Post task execution logs
[2025-07-09T20:16:13.396+0000] {taskinstance.py:2905} ERROR - Task failed with exception
Traceback (most recent call last):
  File "/home/airflow/.local/lib/python3.12/site-packages/airflow/models/taskinstance.py", line 465, in _execute_task
    result = _execute_callable(context=context, **execute_callable_kwargs)
             ^^^^^^^^^^^^^^^^^^^^^^^^^^^^^^^^^^^^^^^^^^^^^^^^^^^^^^^^^^^^^
  File "/home/airflow/.local/lib/python3.12/site-packages/airflow/models/taskinstance.py", line 432, in _execute_callable
    return execute_callable(context=context, **execute_callable_kwargs)
           ^^^^^^^^^^^^^^^^^^^^^^^^^^^^^^^^^^^^^^^^^^^^^^^^^^^^^^^^^^^^
  File "/home/airflow/.local/lib/python3.12/site-packages/airflow/models/baseoperator.py", line 400, in wrapper
    return func(self, *args, **kwargs)
           ^^^^^^^^^^^^^^^^^^^^^^^^^^^
  File "/home/airflow/.local/lib/python3.12/site-packages/airflow/operators/python.py", line 235, in execute
    return_value = self.execute_callable()
                   ^^^^^^^^^^^^^^^^^^^^^^^
  File "/home/airflow/.local/lib/python3.12/site-packages/airflow/operators/python.py", line 252, in execute_callable
    return self.python_callable(*self.op_args, **self.op_kwargs)
           ^^^^^^^^^^^^^^^^^^^^^^^^^^^^^^^^^^^^^^^^^^^^^^^^^^^^^
  File "/opt/airflow/dags/daily_monitoring_dag.py", line 65, in run_monitoring_wrapper
    run_monitoring(reference_ts=ref_ts, current_ts=cur_ts)
  File "/opt/airflow/github_pipeline/monitor.py", line 48, in run_monitoring
    raise FileNotFoundError(f"[ERROR] Reference file not found: {ref_file}")
FileNotFoundError: [ERROR] Reference file not found: features/actor_features_2025-07-04-15.parquet
[2025-07-09T20:16:13.448+0000] {taskinstance.py:1206} INFO - Marking task as UP_FOR_RETRY. dag_id=daily_monitoring_dag, task_id=run_drift_monitoring, run_id=manual__2025-07-09T20:16:08.855380+00:00, execution_date=20250709T201608, start_date=20250709T201613, end_date=20250709T201613
[2025-07-09T20:16:13.488+0000] {standard_task_runner.py:110} ERROR - Failed to execute job 58 for task run_drift_monitoring ([ERROR] Reference file not found: features/actor_features_2025-07-04-15.parquet; 332)
[2025-07-09T20:16:13.510+0000] {local_task_job_runner.py:240} INFO - Task exited with return code 1
[2025-07-09T20:16:13.526+0000] {taskinstance.py:3498} INFO - 0 downstream tasks scheduled from follow-on schedule check
[2025-07-09T20:16:13.527+0000] {local_task_job_runner.py:222} INFO - ::endgroup::
