[2025-07-04T14:45:37.988+0000] {local_task_job_runner.py:120} INFO - ::group::Pre task execution logs
[2025-07-04T14:45:38.084+0000] {taskinstance.py:2076} INFO - Dependencies all met for dep_context=non-requeueable deps ti=<TaskInstance: daily_github_inference.run_inference manual__2025-07-04T14:45:36.737885+00:00 [queued]>
[2025-07-04T14:45:38.131+0000] {taskinstance.py:2076} INFO - Dependencies all met for dep_context=requeueable deps ti=<TaskInstance: daily_github_inference.run_inference manual__2025-07-04T14:45:36.737885+00:00 [queued]>
[2025-07-04T14:45:38.136+0000] {taskinstance.py:2306} INFO - Starting attempt 1 of 2
[2025-07-04T14:45:38.194+0000] {taskinstance.py:2330} INFO - Executing <Task(PythonOperator): run_inference> on 2025-07-04 14:45:36.737885+00:00
[2025-07-04T14:45:38.223+0000] {logging_mixin.py:188} WARNING - /home/***/.local/lib/python3.12/site-packages/***/task/task_runner/standard_task_runner.py:61 DeprecationWarning: This process (pid=263) is multi-threaded, use of fork() may lead to deadlocks in the child.
[2025-07-04T14:45:38.224+0000] {standard_task_runner.py:63} INFO - Started process 267 to run task
[2025-07-04T14:45:38.224+0000] {standard_task_runner.py:90} INFO - Running: ['***', 'tasks', 'run', 'daily_github_inference', 'run_inference', 'manual__2025-07-04T14:45:36.737885+00:00', '--job-id', '3', '--raw', '--subdir', 'DAGS_FOLDER/inference_dag.py', '--cfg-path', '/tmp/tmp63s31exb']
[2025-07-04T14:45:38.228+0000] {standard_task_runner.py:91} INFO - Job 3: Subtask run_inference
[2025-07-04T14:45:38.254+0000] {logging_mixin.py:188} WARNING - /home/***/.local/lib/python3.12/site-packages/***/settings.py:195 DeprecationWarning: The sql_alchemy_conn option in [core] has been moved to the sql_alchemy_conn option in [database] - the old setting has been used, but please update your config.
[2025-07-04T14:45:38.294+0000] {task_command.py:426} INFO - Running <TaskInstance: daily_github_inference.run_inference manual__2025-07-04T14:45:36.737885+00:00 [running]> on host e8e8a486d025
[2025-07-04T14:45:39.035+0000] {taskinstance.py:2648} INFO - Exporting env vars: AIRFLOW_CTX_DAG_OWNER='rajat' AIRFLOW_CTX_DAG_ID='daily_github_inference' AIRFLOW_CTX_TASK_ID='run_inference' AIRFLOW_CTX_EXECUTION_DATE='2025-07-04T14:45:36.737885+00:00' AIRFLOW_CTX_TRY_NUMBER='1' AIRFLOW_CTX_DAG_RUN_ID='manual__2025-07-04T14:45:36.737885+00:00'
[2025-07-04T14:45:39.038+0000] {taskinstance.py:430} INFO - ::endgroup::
[2025-07-04T14:45:39.174+0000] {logging_mixin.py:188} INFO - [INFO] Running inference for timestamp: 2025-07-04-15
[2025-07-04T14:45:39.175+0000] {taskinstance.py:441} INFO - ::group::Post task execution logs
[2025-07-04T14:45:39.177+0000] {taskinstance.py:2905} ERROR - Task failed with exception
Traceback (most recent call last):
  File "/home/airflow/.local/lib/python3.12/site-packages/airflow/models/taskinstance.py", line 465, in _execute_task
    result = _execute_callable(context=context, **execute_callable_kwargs)
             ^^^^^^^^^^^^^^^^^^^^^^^^^^^^^^^^^^^^^^^^^^^^^^^^^^^^^^^^^^^^^
  File "/home/airflow/.local/lib/python3.12/site-packages/airflow/models/taskinstance.py", line 432, in _execute_callable
    return execute_callable(context=context, **execute_callable_kwargs)
           ^^^^^^^^^^^^^^^^^^^^^^^^^^^^^^^^^^^^^^^^^^^^^^^^^^^^^^^^^^^^
  File "/home/airflow/.local/lib/python3.12/site-packages/airflow/models/baseoperator.py", line 400, in wrapper
    return func(self, *args, **kwargs)
           ^^^^^^^^^^^^^^^^^^^^^^^^^^^
  File "/home/airflow/.local/lib/python3.12/site-packages/airflow/operators/python.py", line 235, in execute
    return_value = self.execute_callable()
                   ^^^^^^^^^^^^^^^^^^^^^^^
  File "/home/airflow/.local/lib/python3.12/site-packages/airflow/operators/python.py", line 252, in execute_callable
    return self.python_callable(*self.op_args, **self.op_kwargs)
           ^^^^^^^^^^^^^^^^^^^^^^^^^^^^^^^^^^^^^^^^^^^^^^^^^^^^^
  File "/opt/airflow/dags/inference_dag.py", line 13, in run_daily_inference
    run_inference(timestamp=timestamp)
  File "/opt/airflow/github_pipeline/inference.py", line 16, in run_inference
    raise FileNotFoundError(f"[ERROR] Input file {input_file} not found.")
FileNotFoundError: [ERROR] Input file data/features/actor_features_2025-07-04-15.parquet not found.
[2025-07-04T14:45:39.215+0000] {taskinstance.py:1206} INFO - Marking task as UP_FOR_RETRY. dag_id=daily_github_inference, task_id=run_inference, run_id=manual__2025-07-04T14:45:36.737885+00:00, execution_date=20250704T144536, start_date=20250704T144538, end_date=20250704T144539
[2025-07-04T14:45:39.263+0000] {standard_task_runner.py:110} ERROR - Failed to execute job 3 for task run_inference ([ERROR] Input file data/features/actor_features_2025-07-04-15.parquet not found.; 267)
[2025-07-04T14:45:39.320+0000] {local_task_job_runner.py:240} INFO - Task exited with return code 1
[2025-07-04T14:45:39.332+0000] {taskinstance.py:3498} INFO - 0 downstream tasks scheduled from follow-on schedule check
[2025-07-04T14:45:39.333+0000] {local_task_job_runner.py:222} INFO - ::endgroup::
