[2025-07-04T12:35:44.981+0000] {local_task_job_runner.py:120} INFO - ::group::Pre task execution logs
[2025-07-04T12:35:45.018+0000] {taskinstance.py:2076} INFO - Dependencies all met for dep_context=non-requeueable deps ti=<TaskInstance: weekly_model_retraining.retrain_model scheduled__2025-06-22T00:00:00+00:00 [queued]>
[2025-07-04T12:35:45.026+0000] {taskinstance.py:2076} INFO - Dependencies all met for dep_context=requeueable deps ti=<TaskInstance: weekly_model_retraining.retrain_model scheduled__2025-06-22T00:00:00+00:00 [queued]>
[2025-07-04T12:35:45.027+0000] {taskinstance.py:2306} INFO - Starting attempt 1 of 2
[2025-07-04T12:35:45.041+0000] {taskinstance.py:2330} INFO - Executing <Task(PythonOperator): retrain_model> on 2025-06-22 00:00:00+00:00
[2025-07-04T12:35:45.053+0000] {logging_mixin.py:188} WARNING - /home/***/.local/lib/python3.12/site-packages/***/task/task_runner/standard_task_runner.py:61 DeprecationWarning: This process (pid=504) is multi-threaded, use of fork() may lead to deadlocks in the child.
[2025-07-04T12:35:45.055+0000] {standard_task_runner.py:63} INFO - Started process 511 to run task
[2025-07-04T12:35:45.059+0000] {standard_task_runner.py:90} INFO - Running: ['***', 'tasks', 'run', 'weekly_model_retraining', 'retrain_model', 'scheduled__2025-06-22T00:00:00+00:00', '--job-id', '5', '--raw', '--subdir', 'DAGS_FOLDER/retraining_dag.py', '--cfg-path', '/tmp/tmp4mcb2ikn']
[2025-07-04T12:35:45.063+0000] {standard_task_runner.py:91} INFO - Job 5: Subtask retrain_model
[2025-07-04T12:35:45.080+0000] {logging_mixin.py:188} WARNING - /home/***/.local/lib/python3.12/site-packages/***/settings.py:195 DeprecationWarning: The sql_alchemy_conn option in [core] has been moved to the sql_alchemy_conn option in [database] - the old setting has been used, but please update your config.
[2025-07-04T12:35:45.122+0000] {task_command.py:426} INFO - Running <TaskInstance: weekly_model_retraining.retrain_model scheduled__2025-06-22T00:00:00+00:00 [running]> on host 4be506410e95
[2025-07-04T12:35:45.233+0000] {taskinstance.py:2648} INFO - Exporting env vars: AIRFLOW_CTX_DAG_OWNER='rajat' AIRFLOW_CTX_DAG_ID='weekly_model_retraining' AIRFLOW_CTX_TASK_ID='retrain_model' AIRFLOW_CTX_EXECUTION_DATE='2025-06-22T00:00:00+00:00' AIRFLOW_CTX_TRY_NUMBER='1' AIRFLOW_CTX_DAG_RUN_ID='scheduled__2025-06-22T00:00:00+00:00'
[2025-07-04T12:35:45.234+0000] {taskinstance.py:430} INFO - ::endgroup::
[2025-07-04T12:35:45.255+0000] {logging_mixin.py:188} INFO - [INFO] Starting model retraining...
[2025-07-04T12:35:45.386+0000] {logging_mixin.py:188} WARNING - 2025/07/04 12:35:45 INFO mlflow.tracking.fluent: Experiment with name 'anomaly_detection_github' does not exist. Creating a new experiment.
[2025-07-04T12:35:45.462+0000] {logging_mixin.py:188} WARNING - 2025/07/04 12:35:45 WARNING mlflow.utils.git_utils: Failed to import Git (the Git executable is probably not on your PATH), so Git SHA is not available. Error: Failed to initialize: Bad git executable.
The git executable must be specified in one of the following ways:
    - be included in your $PATH
    - be set via $GIT_PYTHON_GIT_EXECUTABLE
    - explicitly set via git.refresh(<full-path-to-git-executable>)

All git commands will error until this is rectified.

This initial message can be silenced or aggravated in the future by setting the
$GIT_PYTHON_REFRESH environment variable. Use one of the following values:
    - quiet|q|silence|s|silent|none|n|0: for no message or exception
    - warn|w|warning|log|l|1: for a warning message (logging level CRITICAL, displayed by default)
    - error|e|exception|raise|r|2: for a raised exception

Example:
    export GIT_PYTHON_REFRESH=quiet
[2025-07-04T12:35:45.946+0000] {logging_mixin.py:188} INFO -          actor  anomaly_score  anomaly
0  000000armor       0.247586    False
1       000hen       0.254239    False
2        00mjk       0.163571    False
3    01-Deepak       0.247586    False
4  01000110010       0.254239    False
[2025-07-04T12:35:45.975+0000] {logging_mixin.py:188} INFO - [INFO] Retraining completed successfully.
[2025-07-04T12:35:45.976+0000] {python.py:237} INFO - Done. Returned value was: None
[2025-07-04T12:35:45.976+0000] {taskinstance.py:441} INFO - ::group::Post task execution logs
[2025-07-04T12:35:45.983+0000] {taskinstance.py:1206} INFO - Marking task as SUCCESS. dag_id=weekly_model_retraining, task_id=retrain_model, run_id=scheduled__2025-06-22T00:00:00+00:00, execution_date=20250622T000000, start_date=20250704T123545, end_date=20250704T123545
[2025-07-04T12:35:46.035+0000] {local_task_job_runner.py:240} INFO - Task exited with return code 0
[2025-07-04T12:35:46.047+0000] {taskinstance.py:3498} INFO - 0 downstream tasks scheduled from follow-on schedule check
[2025-07-04T12:35:46.048+0000] {local_task_job_runner.py:222} INFO - ::endgroup::
[2025-07-04T14:35:41.245+0000] {local_task_job_runner.py:120} INFO - ::group::Pre task execution logs
[2025-07-04T14:35:41.367+0000] {taskinstance.py:2076} INFO - Dependencies all met for dep_context=non-requeueable deps ti=<TaskInstance: weekly_model_retraining.retrain_model scheduled__2025-06-22T00:00:00+00:00 [queued]>
[2025-07-04T14:35:41.386+0000] {taskinstance.py:2076} INFO - Dependencies all met for dep_context=requeueable deps ti=<TaskInstance: weekly_model_retraining.retrain_model scheduled__2025-06-22T00:00:00+00:00 [queued]>
[2025-07-04T14:35:41.387+0000] {taskinstance.py:2306} INFO - Starting attempt 1 of 2
[2025-07-04T14:35:41.421+0000] {taskinstance.py:2330} INFO - Executing <Task(PythonOperator): retrain_model> on 2025-06-22 00:00:00+00:00
[2025-07-04T14:35:41.472+0000] {logging_mixin.py:188} WARNING - /home/***/.local/lib/python3.12/site-packages/***/task/task_runner/standard_task_runner.py:61 DeprecationWarning: This process (pid=211) is multi-threaded, use of fork() may lead to deadlocks in the child.
[2025-07-04T14:35:41.476+0000] {standard_task_runner.py:63} INFO - Started process 218 to run task
[2025-07-04T14:35:41.464+0000] {standard_task_runner.py:90} INFO - Running: ['***', 'tasks', 'run', 'weekly_model_retraining', 'retrain_model', 'scheduled__2025-06-22T00:00:00+00:00', '--job-id', '5', '--raw', '--subdir', 'DAGS_FOLDER/retraining_dag.py', '--cfg-path', '/tmp/tmpjagrg2ul']
[2025-07-04T14:35:41.480+0000] {standard_task_runner.py:91} INFO - Job 5: Subtask retrain_model
[2025-07-04T14:35:41.512+0000] {logging_mixin.py:188} WARNING - /home/***/.local/lib/python3.12/site-packages/***/settings.py:195 DeprecationWarning: The sql_alchemy_conn option in [core] has been moved to the sql_alchemy_conn option in [database] - the old setting has been used, but please update your config.
[2025-07-04T14:35:41.641+0000] {task_command.py:426} INFO - Running <TaskInstance: weekly_model_retraining.retrain_model scheduled__2025-06-22T00:00:00+00:00 [running]> on host a4cd470c7ef1
[2025-07-04T14:35:42.070+0000] {taskinstance.py:2648} INFO - Exporting env vars: AIRFLOW_CTX_DAG_OWNER='rajat' AIRFLOW_CTX_DAG_ID='weekly_model_retraining' AIRFLOW_CTX_TASK_ID='retrain_model' AIRFLOW_CTX_EXECUTION_DATE='2025-06-22T00:00:00+00:00' AIRFLOW_CTX_TRY_NUMBER='1' AIRFLOW_CTX_DAG_RUN_ID='scheduled__2025-06-22T00:00:00+00:00'
[2025-07-04T14:35:42.075+0000] {taskinstance.py:430} INFO - ::endgroup::
[2025-07-04T14:35:42.231+0000] {logging_mixin.py:188} INFO - [INFO] Starting model training...
[2025-07-04T14:35:42.239+0000] {taskinstance.py:441} INFO - ::group::Post task execution logs
[2025-07-04T14:35:42.244+0000] {taskinstance.py:2905} ERROR - Task failed with exception
Traceback (most recent call last):
  File "/home/airflow/.local/lib/python3.12/site-packages/airflow/models/taskinstance.py", line 465, in _execute_task
    result = _execute_callable(context=context, **execute_callable_kwargs)
             ^^^^^^^^^^^^^^^^^^^^^^^^^^^^^^^^^^^^^^^^^^^^^^^^^^^^^^^^^^^^^
  File "/home/airflow/.local/lib/python3.12/site-packages/airflow/models/taskinstance.py", line 432, in _execute_callable
    return execute_callable(context=context, **execute_callable_kwargs)
           ^^^^^^^^^^^^^^^^^^^^^^^^^^^^^^^^^^^^^^^^^^^^^^^^^^^^^^^^^^^^
  File "/home/airflow/.local/lib/python3.12/site-packages/airflow/models/baseoperator.py", line 400, in wrapper
    return func(self, *args, **kwargs)
           ^^^^^^^^^^^^^^^^^^^^^^^^^^^
  File "/home/airflow/.local/lib/python3.12/site-packages/airflow/operators/python.py", line 235, in execute
    return_value = self.execute_callable()
                   ^^^^^^^^^^^^^^^^^^^^^^^
  File "/home/airflow/.local/lib/python3.12/site-packages/airflow/operators/python.py", line 252, in execute_callable
    return self.python_callable(*self.op_args, **self.op_kwargs)
           ^^^^^^^^^^^^^^^^^^^^^^^^^^^^^^^^^^^^^^^^^^^^^^^^^^^^^
  File "/opt/airflow/github_pipeline/train_model.py", line 77, in main
    run_training(timestamp)
  File "/opt/airflow/github_pipeline/train_model.py", line 25, in run_training
    raise FileNotFoundError(f"[ERROR] Input file not found: {input_file}")
FileNotFoundError: [ERROR] Input file not found: data/features/actor_features_2025-07-04-13.parquet
[2025-07-04T14:35:42.290+0000] {taskinstance.py:1206} INFO - Marking task as UP_FOR_RETRY. dag_id=weekly_model_retraining, task_id=retrain_model, run_id=scheduled__2025-06-22T00:00:00+00:00, execution_date=20250622T000000, start_date=20250704T143541, end_date=20250704T143542
[2025-07-04T14:35:42.390+0000] {standard_task_runner.py:110} ERROR - Failed to execute job 5 for task retrain_model ([ERROR] Input file not found: data/features/actor_features_2025-07-04-13.parquet; 218)
[2025-07-04T14:35:42.491+0000] {local_task_job_runner.py:240} INFO - Task exited with return code 1
[2025-07-04T14:35:42.535+0000] {local_task_job_runner.py:222} INFO - ::endgroup::
[2025-07-04T14:45:53.161+0000] {local_task_job_runner.py:120} INFO - ::group::Pre task execution logs
[2025-07-04T14:45:53.341+0000] {taskinstance.py:2076} INFO - Dependencies all met for dep_context=non-requeueable deps ti=<TaskInstance: weekly_model_retraining.retrain_model scheduled__2025-06-22T00:00:00+00:00 [queued]>
[2025-07-04T14:45:53.362+0000] {taskinstance.py:2076} INFO - Dependencies all met for dep_context=requeueable deps ti=<TaskInstance: weekly_model_retraining.retrain_model scheduled__2025-06-22T00:00:00+00:00 [queued]>
[2025-07-04T14:45:53.362+0000] {taskinstance.py:2306} INFO - Starting attempt 1 of 2
[2025-07-04T14:45:53.393+0000] {taskinstance.py:2330} INFO - Executing <Task(PythonOperator): retrain_model> on 2025-06-22 00:00:00+00:00
[2025-07-04T14:45:53.418+0000] {logging_mixin.py:188} WARNING - /home/***/.local/lib/python3.12/site-packages/***/task/task_runner/standard_task_runner.py:61 DeprecationWarning: This process (pid=282) is multi-threaded, use of fork() may lead to deadlocks in the child.
[2025-07-04T14:45:53.425+0000] {standard_task_runner.py:63} INFO - Started process 295 to run task
[2025-07-04T14:45:53.416+0000] {standard_task_runner.py:90} INFO - Running: ['***', 'tasks', 'run', 'weekly_model_retraining', 'retrain_model', 'scheduled__2025-06-22T00:00:00+00:00', '--job-id', '6', '--raw', '--subdir', 'DAGS_FOLDER/retraining_dag.py', '--cfg-path', '/tmp/tmpopu89peu']
[2025-07-04T14:45:53.427+0000] {standard_task_runner.py:91} INFO - Job 6: Subtask retrain_model
[2025-07-04T14:45:53.452+0000] {logging_mixin.py:188} WARNING - /home/***/.local/lib/python3.12/site-packages/***/settings.py:195 DeprecationWarning: The sql_alchemy_conn option in [core] has been moved to the sql_alchemy_conn option in [database] - the old setting has been used, but please update your config.
[2025-07-04T14:45:53.528+0000] {task_command.py:426} INFO - Running <TaskInstance: weekly_model_retraining.retrain_model scheduled__2025-06-22T00:00:00+00:00 [running]> on host e8e8a486d025
[2025-07-04T14:45:53.678+0000] {taskinstance.py:2648} INFO - Exporting env vars: AIRFLOW_CTX_DAG_OWNER='rajat' AIRFLOW_CTX_DAG_ID='weekly_model_retraining' AIRFLOW_CTX_TASK_ID='retrain_model' AIRFLOW_CTX_EXECUTION_DATE='2025-06-22T00:00:00+00:00' AIRFLOW_CTX_TRY_NUMBER='1' AIRFLOW_CTX_DAG_RUN_ID='scheduled__2025-06-22T00:00:00+00:00'
[2025-07-04T14:45:53.681+0000] {taskinstance.py:430} INFO - ::endgroup::
[2025-07-04T14:45:53.717+0000] {logging_mixin.py:188} INFO - [INFO] Found latest timestamp: 2024-01-01-16
[2025-07-04T14:45:53.719+0000] {logging_mixin.py:188} INFO - [INFO] Starting model training...
[2025-07-04T14:45:54.029+0000] {logging_mixin.py:188} WARNING - 2025/07/04 14:45:54 INFO mlflow.tracking.fluent: Experiment with name 'anomaly_detection_github' does not exist. Creating a new experiment.
[2025-07-04T14:45:54.170+0000] {logging_mixin.py:188} WARNING - 2025/07/04 14:45:54 WARNING mlflow.utils.git_utils: Failed to import Git (the Git executable is probably not on your PATH), so Git SHA is not available. Error: Failed to initialize: Bad git executable.
The git executable must be specified in one of the following ways:
    - be included in your $PATH
    - be set via $GIT_PYTHON_GIT_EXECUTABLE
    - explicitly set via git.refresh(<full-path-to-git-executable>)

All git commands will error until this is rectified.

This initial message can be silenced or aggravated in the future by setting the
$GIT_PYTHON_REFRESH environment variable. Use one of the following values:
    - quiet|q|silence|s|silent|none|n|0: for no message or exception
    - warn|w|warning|log|l|1: for a warning message (logging level CRITICAL, displayed by default)
    - error|e|exception|raise|r|2: for a raised exception

Example:
    export GIT_PYTHON_REFRESH=quiet
[2025-07-04T14:45:55.380+0000] {logging_mixin.py:188} INFO -        actor  anomaly_score  anomaly
0    00000o1       0.208115    False
1     00b7ce       0.246393    False
2  01-Deepak       0.246393    False
3      0130w       0.221535    False
4    01anuja       0.236908    False
[2025-07-04T14:45:55.385+0000] {logging_mixin.py:188} INFO - [INFO] Training completed successfully.
[2025-07-04T14:45:55.388+0000] {python.py:237} INFO - Done. Returned value was: None
[2025-07-04T14:45:55.388+0000] {taskinstance.py:441} INFO - ::group::Post task execution logs
[2025-07-04T14:45:55.405+0000] {taskinstance.py:1206} INFO - Marking task as SUCCESS. dag_id=weekly_model_retraining, task_id=retrain_model, run_id=scheduled__2025-06-22T00:00:00+00:00, execution_date=20250622T000000, start_date=20250704T144553, end_date=20250704T144555
[2025-07-04T14:45:55.466+0000] {local_task_job_runner.py:240} INFO - Task exited with return code 0
[2025-07-04T14:45:55.491+0000] {taskinstance.py:3498} INFO - 0 downstream tasks scheduled from follow-on schedule check
[2025-07-04T14:45:55.494+0000] {local_task_job_runner.py:222} INFO - ::endgroup::
[2025-07-04T15:50:37.163+0000] {local_task_job_runner.py:120} INFO - ::group::Pre task execution logs
[2025-07-04T15:50:37.206+0000] {taskinstance.py:2076} INFO - Dependencies all met for dep_context=non-requeueable deps ti=<TaskInstance: weekly_model_retraining.retrain_model scheduled__2025-06-22T00:00:00+00:00 [queued]>
[2025-07-04T15:50:37.240+0000] {taskinstance.py:2076} INFO - Dependencies all met for dep_context=requeueable deps ti=<TaskInstance: weekly_model_retraining.retrain_model scheduled__2025-06-22T00:00:00+00:00 [queued]>
[2025-07-04T15:50:37.241+0000] {taskinstance.py:2306} INFO - Starting attempt 1 of 2
[2025-07-04T15:50:37.277+0000] {taskinstance.py:2330} INFO - Executing <Task(PythonOperator): retrain_model> on 2025-06-22 00:00:00+00:00
[2025-07-04T15:50:37.294+0000] {logging_mixin.py:188} WARNING - /home/***/.local/lib/python3.12/site-packages/***/task/task_runner/standard_task_runner.py:61 DeprecationWarning: This process (pid=250) is multi-threaded, use of fork() may lead to deadlocks in the child.
[2025-07-04T15:50:37.295+0000] {standard_task_runner.py:63} INFO - Started process 257 to run task
[2025-07-04T15:50:37.292+0000] {standard_task_runner.py:90} INFO - Running: ['***', 'tasks', 'run', 'weekly_model_retraining', 'retrain_model', 'scheduled__2025-06-22T00:00:00+00:00', '--job-id', '7', '--raw', '--subdir', 'DAGS_FOLDER/retraining_dag.py', '--cfg-path', '/tmp/tmp65x08z5z']
[2025-07-04T15:50:37.297+0000] {standard_task_runner.py:91} INFO - Job 7: Subtask retrain_model
[2025-07-04T15:50:37.313+0000] {logging_mixin.py:188} WARNING - /home/***/.local/lib/python3.12/site-packages/***/settings.py:195 DeprecationWarning: The sql_alchemy_conn option in [core] has been moved to the sql_alchemy_conn option in [database] - the old setting has been used, but please update your config.
[2025-07-04T15:50:37.351+0000] {task_command.py:426} INFO - Running <TaskInstance: weekly_model_retraining.retrain_model scheduled__2025-06-22T00:00:00+00:00 [running]> on host feb6e6e9f62a
[2025-07-04T15:50:37.447+0000] {taskinstance.py:2648} INFO - Exporting env vars: AIRFLOW_CTX_DAG_OWNER='rajat' AIRFLOW_CTX_DAG_ID='weekly_model_retraining' AIRFLOW_CTX_TASK_ID='retrain_model' AIRFLOW_CTX_EXECUTION_DATE='2025-06-22T00:00:00+00:00' AIRFLOW_CTX_TRY_NUMBER='1' AIRFLOW_CTX_DAG_RUN_ID='scheduled__2025-06-22T00:00:00+00:00'
[2025-07-04T15:50:37.449+0000] {taskinstance.py:430} INFO - ::endgroup::
[2025-07-04T15:50:37.472+0000] {logging_mixin.py:188} INFO - [INFO] Found latest timestamp: 2024-01-01-16
[2025-07-04T15:50:37.473+0000] {logging_mixin.py:188} INFO - [INFO] Starting model training...
[2025-07-04T15:50:37.561+0000] {logging_mixin.py:188} WARNING - 2025/07/04 15:50:37 INFO mlflow.tracking.fluent: Experiment with name 'anomaly_detection_github' does not exist. Creating a new experiment.
[2025-07-04T15:50:37.625+0000] {logging_mixin.py:188} WARNING - 2025/07/04 15:50:37 WARNING mlflow.utils.git_utils: Failed to import Git (the Git executable is probably not on your PATH), so Git SHA is not available. Error: Failed to initialize: Bad git executable.
The git executable must be specified in one of the following ways:
    - be included in your $PATH
    - be set via $GIT_PYTHON_GIT_EXECUTABLE
    - explicitly set via git.refresh(<full-path-to-git-executable>)

All git commands will error until this is rectified.

This initial message can be silenced or aggravated in the future by setting the
$GIT_PYTHON_REFRESH environment variable. Use one of the following values:
    - quiet|q|silence|s|silent|none|n|0: for no message or exception
    - warn|w|warning|log|l|1: for a warning message (logging level CRITICAL, displayed by default)
    - error|e|exception|raise|r|2: for a raised exception

Example:
    export GIT_PYTHON_REFRESH=quiet
[2025-07-04T15:50:38.363+0000] {logging_mixin.py:188} INFO -        actor  anomaly_score  anomaly
0    00000o1       0.208115    False
1     00b7ce       0.246393    False
2  01-Deepak       0.246393    False
3      0130w       0.221535    False
4    01anuja       0.236908    False
[2025-07-04T15:50:38.366+0000] {logging_mixin.py:188} INFO - [INFO] Training completed successfully.
[2025-07-04T15:50:38.367+0000] {python.py:237} INFO - Done. Returned value was: None
[2025-07-04T15:50:38.367+0000] {taskinstance.py:441} INFO - ::group::Post task execution logs
[2025-07-04T15:50:38.385+0000] {taskinstance.py:1206} INFO - Marking task as SUCCESS. dag_id=weekly_model_retraining, task_id=retrain_model, run_id=scheduled__2025-06-22T00:00:00+00:00, execution_date=20250622T000000, start_date=20250704T155037, end_date=20250704T155038
[2025-07-04T15:50:38.437+0000] {local_task_job_runner.py:240} INFO - Task exited with return code 0
[2025-07-04T15:50:38.452+0000] {taskinstance.py:3498} INFO - 0 downstream tasks scheduled from follow-on schedule check
[2025-07-04T15:50:38.453+0000] {local_task_job_runner.py:222} INFO - ::endgroup::
[2025-07-04T17:49:21.691+0000] {local_task_job_runner.py:120} INFO - ::group::Pre task execution logs
[2025-07-04T17:49:21.756+0000] {taskinstance.py:2076} INFO - Dependencies all met for dep_context=non-requeueable deps ti=<TaskInstance: weekly_model_retraining.retrain_model scheduled__2025-06-22T00:00:00+00:00 [queued]>
[2025-07-04T17:49:21.773+0000] {taskinstance.py:2076} INFO - Dependencies all met for dep_context=requeueable deps ti=<TaskInstance: weekly_model_retraining.retrain_model scheduled__2025-06-22T00:00:00+00:00 [queued]>
[2025-07-04T17:49:21.773+0000] {taskinstance.py:2306} INFO - Starting attempt 1 of 2
[2025-07-04T17:49:21.801+0000] {taskinstance.py:2330} INFO - Executing <Task(PythonOperator): retrain_model> on 2025-06-22 00:00:00+00:00
[2025-07-04T17:49:21.826+0000] {logging_mixin.py:188} WARNING - /home/***/.local/lib/python3.12/site-packages/***/task/task_runner/standard_task_runner.py:61 DeprecationWarning: This process (pid=502) is multi-threaded, use of fork() may lead to deadlocks in the child.
[2025-07-04T17:49:21.829+0000] {standard_task_runner.py:63} INFO - Started process 511 to run task
[2025-07-04T17:49:21.842+0000] {standard_task_runner.py:90} INFO - Running: ['***', 'tasks', 'run', 'weekly_model_retraining', 'retrain_model', 'scheduled__2025-06-22T00:00:00+00:00', '--job-id', '32', '--raw', '--subdir', 'DAGS_FOLDER/retraining_dag.py', '--cfg-path', '/tmp/tmpxcvm02w2']
[2025-07-04T17:49:21.862+0000] {standard_task_runner.py:91} INFO - Job 32: Subtask retrain_model
[2025-07-04T17:49:21.899+0000] {logging_mixin.py:188} WARNING - /home/***/.local/lib/python3.12/site-packages/***/settings.py:195 DeprecationWarning: The sql_alchemy_conn option in [core] has been moved to the sql_alchemy_conn option in [database] - the old setting has been used, but please update your config.
[2025-07-04T17:49:21.942+0000] {task_command.py:426} INFO - Running <TaskInstance: weekly_model_retraining.retrain_model scheduled__2025-06-22T00:00:00+00:00 [running]> on host 1f9ae480a8ef
[2025-07-04T17:49:22.181+0000] {taskinstance.py:2648} INFO - Exporting env vars: AIRFLOW_CTX_DAG_OWNER='rajat' AIRFLOW_CTX_DAG_ID='weekly_model_retraining' AIRFLOW_CTX_TASK_ID='retrain_model' AIRFLOW_CTX_EXECUTION_DATE='2025-06-22T00:00:00+00:00' AIRFLOW_CTX_TRY_NUMBER='1' AIRFLOW_CTX_DAG_RUN_ID='scheduled__2025-06-22T00:00:00+00:00'
[2025-07-04T17:49:22.182+0000] {taskinstance.py:430} INFO - ::endgroup::
[2025-07-04T17:49:22.198+0000] {logging_mixin.py:188} INFO - [INFO] Found latest timestamp: 2025-07-03-15
[2025-07-04T17:49:22.199+0000] {logging_mixin.py:188} INFO - [INFO] Starting model training...
[2025-07-04T17:49:22.329+0000] {logging_mixin.py:188} WARNING - 2025/07/04 17:49:22 INFO mlflow.tracking.fluent: Experiment with name 'anomaly_detection_github' does not exist. Creating a new experiment.
[2025-07-04T17:49:22.528+0000] {logging_mixin.py:188} WARNING - 2025/07/04 17:49:22 WARNING mlflow.utils.git_utils: Failed to import Git (the Git executable is probably not on your PATH), so Git SHA is not available. Error: Failed to initialize: Bad git executable.
The git executable must be specified in one of the following ways:
    - be included in your $PATH
    - be set via $GIT_PYTHON_GIT_EXECUTABLE
    - explicitly set via git.refresh(<full-path-to-git-executable>)

All git commands will error until this is rectified.

This initial message can be silenced or aggravated in the future by setting the
$GIT_PYTHON_REFRESH environment variable. Use one of the following values:
    - quiet|q|silence|s|silent|none|n|0: for no message or exception
    - warn|w|warning|log|l|1: for a warning message (logging level CRITICAL, displayed by default)
    - error|e|exception|raise|r|2: for a raised exception

Example:
    export GIT_PYTHON_REFRESH=quiet
[2025-07-04T17:49:24.010+0000] {logging_mixin.py:188} INFO -          actor  anomaly_score  anomaly
0   0-kodiya-0       0.285104    False
1  00-10-01-11       0.285104    False
2   001ryu-ryu       0.268308    False
3       0047ol       0.156115    False
4      004Ajay       0.285104    False
[2025-07-04T17:49:24.015+0000] {logging_mixin.py:188} INFO - [INFO] Training completed successfully.
[2025-07-04T17:49:24.019+0000] {python.py:237} INFO - Done. Returned value was: None
[2025-07-04T17:49:24.020+0000] {taskinstance.py:441} INFO - ::group::Post task execution logs
[2025-07-04T17:49:24.043+0000] {taskinstance.py:1206} INFO - Marking task as SUCCESS. dag_id=weekly_model_retraining, task_id=retrain_model, run_id=scheduled__2025-06-22T00:00:00+00:00, execution_date=20250622T000000, start_date=20250704T174921, end_date=20250704T174924
[2025-07-04T17:49:24.110+0000] {local_task_job_runner.py:240} INFO - Task exited with return code 0
[2025-07-04T17:49:24.131+0000] {taskinstance.py:3498} INFO - 0 downstream tasks scheduled from follow-on schedule check
[2025-07-04T17:49:24.134+0000] {local_task_job_runner.py:222} INFO - ::endgroup::
[2025-07-05T22:48:55.361+0000] {local_task_job_runner.py:120} INFO - ::group::Pre task execution logs
[2025-07-05T22:48:55.416+0000] {taskinstance.py:2076} INFO - Dependencies all met for dep_context=non-requeueable deps ti=<TaskInstance: weekly_model_retraining.retrain_model scheduled__2025-06-22T00:00:00+00:00 [queued]>
[2025-07-05T22:48:55.424+0000] {taskinstance.py:2076} INFO - Dependencies all met for dep_context=requeueable deps ti=<TaskInstance: weekly_model_retraining.retrain_model scheduled__2025-06-22T00:00:00+00:00 [queued]>
[2025-07-05T22:48:55.424+0000] {taskinstance.py:2306} INFO - Starting attempt 1 of 2
[2025-07-05T22:48:55.454+0000] {taskinstance.py:2330} INFO - Executing <Task(PythonOperator): retrain_model> on 2025-06-22 00:00:00+00:00
[2025-07-05T22:48:55.479+0000] {standard_task_runner.py:90} INFO - Running: ['***', 'tasks', 'run', 'weekly_model_retraining', 'retrain_model', 'scheduled__2025-06-22T00:00:00+00:00', '--job-id', '12', '--raw', '--subdir', 'DAGS_FOLDER/retraining_dag.py', '--cfg-path', '/tmp/tmp7y_x9qtc']
[2025-07-05T22:48:55.485+0000] {standard_task_runner.py:91} INFO - Job 12: Subtask retrain_model
[2025-07-05T22:48:55.491+0000] {logging_mixin.py:188} WARNING - /home/***/.local/lib/python3.12/site-packages/***/task/task_runner/standard_task_runner.py:61 DeprecationWarning: This process (pid=347) is multi-threaded, use of fork() may lead to deadlocks in the child.
[2025-07-05T22:48:55.493+0000] {standard_task_runner.py:63} INFO - Started process 353 to run task
[2025-07-05T22:48:55.521+0000] {logging_mixin.py:188} WARNING - /home/***/.local/lib/python3.12/site-packages/***/settings.py:195 DeprecationWarning: The sql_alchemy_conn option in [core] has been moved to the sql_alchemy_conn option in [database] - the old setting has been used, but please update your config.
[2025-07-05T22:48:55.620+0000] {task_command.py:426} INFO - Running <TaskInstance: weekly_model_retraining.retrain_model scheduled__2025-06-22T00:00:00+00:00 [running]> on host ca9d5d7b2943
[2025-07-05T22:48:55.746+0000] {taskinstance.py:2648} INFO - Exporting env vars: AIRFLOW_CTX_DAG_OWNER='rajat' AIRFLOW_CTX_DAG_ID='weekly_model_retraining' AIRFLOW_CTX_TASK_ID='retrain_model' AIRFLOW_CTX_EXECUTION_DATE='2025-06-22T00:00:00+00:00' AIRFLOW_CTX_TRY_NUMBER='1' AIRFLOW_CTX_DAG_RUN_ID='scheduled__2025-06-22T00:00:00+00:00'
[2025-07-05T22:48:55.747+0000] {taskinstance.py:430} INFO - ::endgroup::
[2025-07-05T22:48:55.767+0000] {logging_mixin.py:188} INFO - [INFO] Found latest timestamp: 2025-07-04-15
[2025-07-05T22:48:55.767+0000] {logging_mixin.py:188} INFO - [INFO] Starting model training...
[2025-07-05T22:48:55.900+0000] {connectionpool.py:874} WARNING - Retrying (Retry(total=6, connect=6, read=7, redirect=7, status=7)) after connection broken by 'NameResolutionError("<urllib3.connection.HTTPConnection object at 0x733a211f0e00>: Failed to resolve 'mlflow-server' ([Errno -2] Name or service not known)")': /api/2.0/mlflow/experiments/get-by-name?experiment_name=anomaly_detection_github
[2025-07-05T22:49:00.289+0000] {connectionpool.py:874} WARNING - Retrying (Retry(total=5, connect=5, read=7, redirect=7, status=7)) after connection broken by 'NameResolutionError("<urllib3.connection.HTTPConnection object at 0x733a20cd6900>: Failed to resolve 'mlflow-server' ([Errno -2] Name or service not known)")': /api/2.0/mlflow/experiments/get-by-name?experiment_name=anomaly_detection_github
[2025-07-05T22:49:09.021+0000] {connectionpool.py:874} WARNING - Retrying (Retry(total=4, connect=4, read=7, redirect=7, status=7)) after connection broken by 'NameResolutionError("<urllib3.connection.HTTPConnection object at 0x733a210b0890>: Failed to resolve 'mlflow-server' ([Errno -2] Name or service not known)")': /api/2.0/mlflow/experiments/get-by-name?experiment_name=anomaly_detection_github
[2025-07-05T22:49:25.982+0000] {connectionpool.py:874} WARNING - Retrying (Retry(total=3, connect=3, read=7, redirect=7, status=7)) after connection broken by 'NameResolutionError("<urllib3.connection.HTTPConnection object at 0x733a20070050>: Failed to resolve 'mlflow-server' ([Errno -2] Name or service not known)")': /api/2.0/mlflow/experiments/get-by-name?experiment_name=anomaly_detection_github
[2025-07-05T22:49:58.444+0000] {connectionpool.py:874} WARNING - Retrying (Retry(total=2, connect=2, read=7, redirect=7, status=7)) after connection broken by 'NameResolutionError("<urllib3.connection.HTTPConnection object at 0x733a200704a0>: Failed to resolve 'mlflow-server' ([Errno -2] Name or service not known)")': /api/2.0/mlflow/experiments/get-by-name?experiment_name=anomaly_detection_github
[2025-07-05T22:51:02.772+0000] {connectionpool.py:874} WARNING - Retrying (Retry(total=1, connect=1, read=7, redirect=7, status=7)) after connection broken by 'NameResolutionError("<urllib3.connection.HTTPConnection object at 0x733a20070680>: Failed to resolve 'mlflow-server' ([Errno -2] Name or service not known)")': /api/2.0/mlflow/experiments/get-by-name?experiment_name=anomaly_detection_github
[2025-07-05T22:53:02.881+0000] {connectionpool.py:874} WARNING - Retrying (Retry(total=0, connect=0, read=7, redirect=7, status=7)) after connection broken by 'NameResolutionError("<urllib3.connection.HTTPConnection object at 0x733a20071430>: Failed to resolve 'mlflow-server' ([Errno -2] Name or service not known)")': /api/2.0/mlflow/experiments/get-by-name?experiment_name=anomaly_detection_github
[2025-07-05T22:53:02.900+0000] {taskinstance.py:441} INFO - ::group::Post task execution logs
[2025-07-05T22:53:02.901+0000] {taskinstance.py:2905} ERROR - Task failed with exception
Traceback (most recent call last):
  File "/home/airflow/.local/lib/python3.12/site-packages/urllib3/connection.py", line 198, in _new_conn
    sock = connection.create_connection(
           ^^^^^^^^^^^^^^^^^^^^^^^^^^^^^
  File "/home/airflow/.local/lib/python3.12/site-packages/urllib3/util/connection.py", line 60, in create_connection
    for res in socket.getaddrinfo(host, port, family, socket.SOCK_STREAM):
               ^^^^^^^^^^^^^^^^^^^^^^^^^^^^^^^^^^^^^^^^^^^^^^^^^^^^^^^^^^
  File "/usr/local/lib/python3.12/socket.py", line 963, in getaddrinfo
    for res in _socket.getaddrinfo(host, port, family, type, proto, flags):
               ^^^^^^^^^^^^^^^^^^^^^^^^^^^^^^^^^^^^^^^^^^^^^^^^^^^^^^^^^^^
socket.gaierror: [Errno -2] Name or service not known

The above exception was the direct cause of the following exception:

Traceback (most recent call last):
  File "/home/airflow/.local/lib/python3.12/site-packages/urllib3/connectionpool.py", line 793, in urlopen
    response = self._make_request(
               ^^^^^^^^^^^^^^^^^^^
  File "/home/airflow/.local/lib/python3.12/site-packages/urllib3/connectionpool.py", line 496, in _make_request
    conn.request(
  File "/home/airflow/.local/lib/python3.12/site-packages/urllib3/connection.py", line 400, in request
    self.endheaders()
  File "/usr/local/lib/python3.12/http/client.py", line 1331, in endheaders
    self._send_output(message_body, encode_chunked=encode_chunked)
  File "/usr/local/lib/python3.12/http/client.py", line 1091, in _send_output
    self.send(msg)
  File "/usr/local/lib/python3.12/http/client.py", line 1035, in send
    self.connect()
  File "/home/airflow/.local/lib/python3.12/site-packages/urllib3/connection.py", line 238, in connect
    self.sock = self._new_conn()
                ^^^^^^^^^^^^^^^^
  File "/home/airflow/.local/lib/python3.12/site-packages/urllib3/connection.py", line 205, in _new_conn
    raise NameResolutionError(self.host, self, e) from e
urllib3.exceptions.NameResolutionError: <urllib3.connection.HTTPConnection object at 0x733a20071460>: Failed to resolve 'mlflow-server' ([Errno -2] Name or service not known)

The above exception was the direct cause of the following exception:

Traceback (most recent call last):
  File "/home/airflow/.local/lib/python3.12/site-packages/requests/adapters.py", line 667, in send
    resp = conn.urlopen(
           ^^^^^^^^^^^^^
  File "/home/airflow/.local/lib/python3.12/site-packages/urllib3/connectionpool.py", line 877, in urlopen
    return self.urlopen(
           ^^^^^^^^^^^^^
  File "/home/airflow/.local/lib/python3.12/site-packages/urllib3/connectionpool.py", line 877, in urlopen
    return self.urlopen(
           ^^^^^^^^^^^^^
  File "/home/airflow/.local/lib/python3.12/site-packages/urllib3/connectionpool.py", line 877, in urlopen
    return self.urlopen(
           ^^^^^^^^^^^^^
  [Previous line repeated 4 more times]
  File "/home/airflow/.local/lib/python3.12/site-packages/urllib3/connectionpool.py", line 847, in urlopen
    retries = retries.increment(
              ^^^^^^^^^^^^^^^^^^
  File "/home/airflow/.local/lib/python3.12/site-packages/urllib3/util/retry.py", line 515, in increment
    raise MaxRetryError(_pool, url, reason) from reason  # type: ignore[arg-type]
    ^^^^^^^^^^^^^^^^^^^^^^^^^^^^^^^^^^^^^^^^^^^^^^^^^^^
urllib3.exceptions.MaxRetryError: HTTPConnectionPool(host='mlflow-server', port=5000): Max retries exceeded with url: /api/2.0/mlflow/experiments/get-by-name?experiment_name=anomaly_detection_github (Caused by NameResolutionError("<urllib3.connection.HTTPConnection object at 0x733a20071460>: Failed to resolve 'mlflow-server' ([Errno -2] Name or service not known)"))

During handling of the above exception, another exception occurred:

Traceback (most recent call last):
  File "/home/airflow/.local/lib/python3.12/site-packages/mlflow/utils/rest_utils.py", line 229, in http_request
    return _get_http_response_with_retries(
           ^^^^^^^^^^^^^^^^^^^^^^^^^^^^^^^^
  File "/home/airflow/.local/lib/python3.12/site-packages/mlflow/utils/request_utils.py", line 237, in _get_http_response_with_retries
    return session.request(method, url, allow_redirects=allow_redirects, **kwargs)
           ^^^^^^^^^^^^^^^^^^^^^^^^^^^^^^^^^^^^^^^^^^^^^^^^^^^^^^^^^^^^^^^^^^^^^^^
  File "/home/airflow/.local/lib/python3.12/site-packages/requests/sessions.py", line 589, in request
    resp = self.send(prep, **send_kwargs)
           ^^^^^^^^^^^^^^^^^^^^^^^^^^^^^^
  File "/home/airflow/.local/lib/python3.12/site-packages/requests/sessions.py", line 703, in send
    r = adapter.send(request, **kwargs)
        ^^^^^^^^^^^^^^^^^^^^^^^^^^^^^^^
  File "/home/airflow/.local/lib/python3.12/site-packages/requests/adapters.py", line 700, in send
    raise ConnectionError(e, request=request)
requests.exceptions.ConnectionError: HTTPConnectionPool(host='mlflow-server', port=5000): Max retries exceeded with url: /api/2.0/mlflow/experiments/get-by-name?experiment_name=anomaly_detection_github (Caused by NameResolutionError("<urllib3.connection.HTTPConnection object at 0x733a20071460>: Failed to resolve 'mlflow-server' ([Errno -2] Name or service not known)"))

During handling of the above exception, another exception occurred:

Traceback (most recent call last):
  File "/home/airflow/.local/lib/python3.12/site-packages/airflow/models/taskinstance.py", line 465, in _execute_task
    result = _execute_callable(context=context, **execute_callable_kwargs)
             ^^^^^^^^^^^^^^^^^^^^^^^^^^^^^^^^^^^^^^^^^^^^^^^^^^^^^^^^^^^^^
  File "/home/airflow/.local/lib/python3.12/site-packages/airflow/models/taskinstance.py", line 432, in _execute_callable
    return execute_callable(context=context, **execute_callable_kwargs)
           ^^^^^^^^^^^^^^^^^^^^^^^^^^^^^^^^^^^^^^^^^^^^^^^^^^^^^^^^^^^^
  File "/home/airflow/.local/lib/python3.12/site-packages/airflow/models/baseoperator.py", line 400, in wrapper
    return func(self, *args, **kwargs)
           ^^^^^^^^^^^^^^^^^^^^^^^^^^^
  File "/home/airflow/.local/lib/python3.12/site-packages/airflow/operators/python.py", line 235, in execute
    return_value = self.execute_callable()
                   ^^^^^^^^^^^^^^^^^^^^^^^
  File "/home/airflow/.local/lib/python3.12/site-packages/airflow/operators/python.py", line 252, in execute_callable
    return self.python_callable(*self.op_args, **self.op_kwargs)
           ^^^^^^^^^^^^^^^^^^^^^^^^^^^^^^^^^^^^^^^^^^^^^^^^^^^^^
  File "/opt/airflow/github_pipeline/train_model.py", line 100, in main
    run_training(latest_ts)
  File "/opt/airflow/github_pipeline/train_model.py", line 45, in run_training
    mlflow.set_experiment(experiment_name)
  File "/home/airflow/.local/lib/python3.12/site-packages/mlflow/tracking/fluent.py", line 183, in set_experiment
    experiment = client.get_experiment_by_name(experiment_name)
                 ^^^^^^^^^^^^^^^^^^^^^^^^^^^^^^^^^^^^^^^^^^^^^^
  File "/home/airflow/.local/lib/python3.12/site-packages/mlflow/tracking/_tracking_service/client.py", line 258, in get_experiment_by_name
    return self.store.get_experiment_by_name(name)
           ^^^^^^^^^^^^^^^^^^^^^^^^^^^^^^^^^^^^^^^
  File "/home/airflow/.local/lib/python3.12/site-packages/mlflow/store/tracking/rest_store.py", line 869, in get_experiment_by_name
    response_proto = self._call_endpoint(GetExperimentByName, req_body)
                     ^^^^^^^^^^^^^^^^^^^^^^^^^^^^^^^^^^^^^^^^^^^^^^^^^^
  File "/home/airflow/.local/lib/python3.12/site-packages/mlflow/store/tracking/rest_store.py", line 135, in _call_endpoint
    return call_endpoint(
           ^^^^^^^^^^^^^^
  File "/home/airflow/.local/lib/python3.12/site-packages/mlflow/utils/rest_utils.py", line 585, in call_endpoint
    response = http_request(**call_kwargs)
               ^^^^^^^^^^^^^^^^^^^^^^^^^^^
  File "/home/airflow/.local/lib/python3.12/site-packages/mlflow/utils/rest_utils.py", line 252, in http_request
    raise MlflowException(f"API request to {url} failed with exception {e}")
mlflow.exceptions.MlflowException: API request to http://mlflow-server:5000/api/2.0/mlflow/experiments/get-by-name failed with exception HTTPConnectionPool(host='mlflow-server', port=5000): Max retries exceeded with url: /api/2.0/mlflow/experiments/get-by-name?experiment_name=anomaly_detection_github (Caused by NameResolutionError("<urllib3.connection.HTTPConnection object at 0x733a20071460>: Failed to resolve 'mlflow-server' ([Errno -2] Name or service not known)"))
[2025-07-05T22:53:02.963+0000] {taskinstance.py:1206} INFO - Marking task as UP_FOR_RETRY. dag_id=weekly_model_retraining, task_id=retrain_model, run_id=scheduled__2025-06-22T00:00:00+00:00, execution_date=20250622T000000, start_date=20250705T224855, end_date=20250705T225302
[2025-07-05T22:53:02.987+0000] {standard_task_runner.py:110} ERROR - Failed to execute job 12 for task retrain_model (API request to http://mlflow-server:5000/api/2.0/mlflow/experiments/get-by-name failed with exception HTTPConnectionPool(host='mlflow-server', port=5000): Max retries exceeded with url: /api/2.0/mlflow/experiments/get-by-name?experiment_name=anomaly_detection_github (Caused by NameResolutionError("<urllib3.connection.HTTPConnection object at 0x733a20071460>: Failed to resolve 'mlflow-server' ([Errno -2] Name or service not known)")); 353)
[2025-07-05T22:53:03.019+0000] {local_task_job_runner.py:240} INFO - Task exited with return code 1
[2025-07-05T22:53:03.035+0000] {taskinstance.py:3498} INFO - 0 downstream tasks scheduled from follow-on schedule check
[2025-07-05T22:53:03.036+0000] {local_task_job_runner.py:222} INFO - ::endgroup::
[2025-07-05T23:05:20.926+0000] {local_task_job_runner.py:120} INFO - ::group::Pre task execution logs
[2025-07-05T23:05:20.973+0000] {taskinstance.py:2076} INFO - Dependencies all met for dep_context=non-requeueable deps ti=<TaskInstance: weekly_model_retraining.retrain_model scheduled__2025-06-22T00:00:00+00:00 [queued]>
[2025-07-05T23:05:20.984+0000] {taskinstance.py:2076} INFO - Dependencies all met for dep_context=requeueable deps ti=<TaskInstance: weekly_model_retraining.retrain_model scheduled__2025-06-22T00:00:00+00:00 [queued]>
[2025-07-05T23:05:20.985+0000] {taskinstance.py:2306} INFO - Starting attempt 1 of 2
[2025-07-05T23:05:20.996+0000] {taskinstance.py:2330} INFO - Executing <Task(PythonOperator): retrain_model> on 2025-06-22 00:00:00+00:00
[2025-07-05T23:05:21.025+0000] {logging_mixin.py:188} WARNING - /home/***/.local/lib/python3.12/site-packages/***/task/task_runner/standard_task_runner.py:61 DeprecationWarning: This process (pid=200) is multi-threaded, use of fork() may lead to deadlocks in the child.
[2025-07-05T23:05:21.016+0000] {standard_task_runner.py:90} INFO - Running: ['***', 'tasks', 'run', 'weekly_model_retraining', 'retrain_model', 'scheduled__2025-06-22T00:00:00+00:00', '--job-id', '3', '--raw', '--subdir', 'DAGS_FOLDER/retraining_dag.py', '--cfg-path', '/tmp/tmpeb_pozny']
[2025-07-05T23:05:21.028+0000] {standard_task_runner.py:91} INFO - Job 3: Subtask retrain_model
[2025-07-05T23:05:21.028+0000] {standard_task_runner.py:63} INFO - Started process 205 to run task
[2025-07-05T23:05:21.045+0000] {logging_mixin.py:188} WARNING - /home/***/.local/lib/python3.12/site-packages/***/settings.py:195 DeprecationWarning: The sql_alchemy_conn option in [core] has been moved to the sql_alchemy_conn option in [database] - the old setting has been used, but please update your config.
[2025-07-05T23:05:21.082+0000] {task_command.py:426} INFO - Running <TaskInstance: weekly_model_retraining.retrain_model scheduled__2025-06-22T00:00:00+00:00 [running]> on host 69c06594a516
[2025-07-05T23:05:21.221+0000] {taskinstance.py:2648} INFO - Exporting env vars: AIRFLOW_CTX_DAG_OWNER='rajat' AIRFLOW_CTX_DAG_ID='weekly_model_retraining' AIRFLOW_CTX_TASK_ID='retrain_model' AIRFLOW_CTX_EXECUTION_DATE='2025-06-22T00:00:00+00:00' AIRFLOW_CTX_TRY_NUMBER='1' AIRFLOW_CTX_DAG_RUN_ID='scheduled__2025-06-22T00:00:00+00:00'
[2025-07-05T23:05:21.224+0000] {taskinstance.py:430} INFO - ::endgroup::
[2025-07-05T23:05:21.272+0000] {logging_mixin.py:188} INFO - [INFO] Found latest timestamp: 2025-07-04-15
[2025-07-05T23:05:21.272+0000] {logging_mixin.py:188} INFO - [INFO] Starting model training...
[2025-07-05T23:05:22.578+0000] {logging_mixin.py:188} WARNING - 2025/07/05 23:05:22 WARNING mlflow.utils.git_utils: Failed to import Git (the Git executable is probably not on your PATH), so Git SHA is not available. Error: Failed to initialize: Bad git executable.
The git executable must be specified in one of the following ways:
    - be included in your $PATH
    - be set via $GIT_PYTHON_GIT_EXECUTABLE
    - explicitly set via git.refresh(<full-path-to-git-executable>)

All git commands will error until this is rectified.

This initial message can be silenced or aggravated in the future by setting the
$GIT_PYTHON_REFRESH environment variable. Use one of the following values:
    - quiet|q|silence|s|silent|none|n|0: for no message or exception
    - warn|w|warning|log|l|1: for a warning message (logging level CRITICAL, displayed by default)
    - error|e|exception|raise|r|2: for a raised exception

Example:
    export GIT_PYTHON_REFRESH=quiet
[2025-07-05T23:05:23.455+0000] {logging_mixin.py:188} INFO - 🏃 View run clean-elk-342 at: http://mlflow-server:5000/#/experiments/1/runs/296276a38ee242b89a68b8feb3a78e11
[2025-07-05T23:05:23.455+0000] {logging_mixin.py:188} INFO - 🧪 View experiment at: http://mlflow-server:5000/#/experiments/1
[2025-07-05T23:05:23.471+0000] {taskinstance.py:441} INFO - ::group::Post task execution logs
[2025-07-05T23:05:23.471+0000] {taskinstance.py:2905} ERROR - Task failed with exception
Traceback (most recent call last):
  File "/home/airflow/.local/lib/python3.12/site-packages/airflow/models/taskinstance.py", line 465, in _execute_task
    result = _execute_callable(context=context, **execute_callable_kwargs)
             ^^^^^^^^^^^^^^^^^^^^^^^^^^^^^^^^^^^^^^^^^^^^^^^^^^^^^^^^^^^^^
  File "/home/airflow/.local/lib/python3.12/site-packages/airflow/models/taskinstance.py", line 432, in _execute_callable
    return execute_callable(context=context, **execute_callable_kwargs)
           ^^^^^^^^^^^^^^^^^^^^^^^^^^^^^^^^^^^^^^^^^^^^^^^^^^^^^^^^^^^^
  File "/home/airflow/.local/lib/python3.12/site-packages/airflow/models/baseoperator.py", line 400, in wrapper
    return func(self, *args, **kwargs)
           ^^^^^^^^^^^^^^^^^^^^^^^^^^^
  File "/home/airflow/.local/lib/python3.12/site-packages/airflow/operators/python.py", line 235, in execute
    return_value = self.execute_callable()
                   ^^^^^^^^^^^^^^^^^^^^^^^
  File "/home/airflow/.local/lib/python3.12/site-packages/airflow/operators/python.py", line 252, in execute_callable
    return self.python_callable(*self.op_args, **self.op_kwargs)
           ^^^^^^^^^^^^^^^^^^^^^^^^^^^^^^^^^^^^^^^^^^^^^^^^^^^^^
  File "/opt/airflow/github_pipeline/train_model.py", line 100, in main
    run_training(latest_ts)
  File "/opt/airflow/github_pipeline/train_model.py", line 60, in run_training
    mlflow.log_artifact(str(model_file))
  File "/home/airflow/.local/lib/python3.12/site-packages/mlflow/tracking/fluent.py", line 1404, in log_artifact
    MlflowClient().log_artifact(run_id, local_path, artifact_path)
  File "/home/airflow/.local/lib/python3.12/site-packages/mlflow/tracking/client.py", line 2448, in log_artifact
    self._tracking_client.log_artifact(run_id, local_path, artifact_path)
  File "/home/airflow/.local/lib/python3.12/site-packages/mlflow/tracking/_tracking_service/client.py", line 639, in log_artifact
    artifact_repo.log_artifact(local_path, artifact_path)
  File "/home/airflow/.local/lib/python3.12/site-packages/mlflow/store/artifact/local_artifact_repo.py", line 43, in log_artifact
    mkdir(artifact_dir)
  File "/home/airflow/.local/lib/python3.12/site-packages/mlflow/utils/file_utils.py", line 209, in mkdir
    raise e
  File "/home/airflow/.local/lib/python3.12/site-packages/mlflow/utils/file_utils.py", line 206, in mkdir
    os.makedirs(target, exist_ok=True)
  File "<frozen os>", line 215, in makedirs
  File "<frozen os>", line 215, in makedirs
  File "<frozen os>", line 215, in makedirs
  File "<frozen os>", line 225, in makedirs
PermissionError: [Errno 13] Permission denied: '/mlflow-artifacts'
[2025-07-05T23:05:23.481+0000] {taskinstance.py:1206} INFO - Marking task as UP_FOR_RETRY. dag_id=weekly_model_retraining, task_id=retrain_model, run_id=scheduled__2025-06-22T00:00:00+00:00, execution_date=20250622T000000, start_date=20250705T230520, end_date=20250705T230523
[2025-07-05T23:05:23.494+0000] {standard_task_runner.py:110} ERROR - Failed to execute job 3 for task retrain_model ([Errno 13] Permission denied: '/mlflow-artifacts'; 205)
[2025-07-05T23:05:23.530+0000] {local_task_job_runner.py:240} INFO - Task exited with return code 1
[2025-07-05T23:05:23.541+0000] {taskinstance.py:3498} INFO - 0 downstream tasks scheduled from follow-on schedule check
[2025-07-05T23:05:23.543+0000] {local_task_job_runner.py:222} INFO - ::endgroup::
[2025-07-05T23:26:15.322+0000] {local_task_job_runner.py:120} INFO - ::group::Pre task execution logs
[2025-07-05T23:26:15.409+0000] {taskinstance.py:2076} INFO - Dependencies all met for dep_context=non-requeueable deps ti=<TaskInstance: weekly_model_retraining.retrain_model scheduled__2025-06-22T00:00:00+00:00 [queued]>
[2025-07-05T23:26:15.425+0000] {taskinstance.py:2076} INFO - Dependencies all met for dep_context=requeueable deps ti=<TaskInstance: weekly_model_retraining.retrain_model scheduled__2025-06-22T00:00:00+00:00 [queued]>
[2025-07-05T23:26:15.427+0000] {taskinstance.py:2306} INFO - Starting attempt 1 of 2
[2025-07-05T23:26:15.453+0000] {taskinstance.py:2330} INFO - Executing <Task(PythonOperator): retrain_model> on 2025-06-22 00:00:00+00:00
[2025-07-05T23:26:15.494+0000] {logging_mixin.py:188} WARNING - /home/***/.local/lib/python3.12/site-packages/***/task/task_runner/standard_task_runner.py:61 DeprecationWarning: This process (pid=287) is multi-threaded, use of fork() may lead to deadlocks in the child.
[2025-07-05T23:26:15.497+0000] {standard_task_runner.py:63} INFO - Started process 298 to run task
[2025-07-05T23:26:15.493+0000] {standard_task_runner.py:90} INFO - Running: ['***', 'tasks', 'run', 'weekly_model_retraining', 'retrain_model', 'scheduled__2025-06-22T00:00:00+00:00', '--job-id', '12', '--raw', '--subdir', 'DAGS_FOLDER/retraining_dag.py', '--cfg-path', '/tmp/tmpexxmeu84']
[2025-07-05T23:26:15.501+0000] {standard_task_runner.py:91} INFO - Job 12: Subtask retrain_model
[2025-07-05T23:26:15.548+0000] {logging_mixin.py:188} WARNING - /home/***/.local/lib/python3.12/site-packages/***/settings.py:195 DeprecationWarning: The sql_alchemy_conn option in [core] has been moved to the sql_alchemy_conn option in [database] - the old setting has been used, but please update your config.
[2025-07-05T23:26:15.613+0000] {task_command.py:426} INFO - Running <TaskInstance: weekly_model_retraining.retrain_model scheduled__2025-06-22T00:00:00+00:00 [running]> on host 9da7b743aeb0
[2025-07-05T23:26:15.783+0000] {taskinstance.py:2648} INFO - Exporting env vars: AIRFLOW_CTX_DAG_OWNER='rajat' AIRFLOW_CTX_DAG_ID='weekly_model_retraining' AIRFLOW_CTX_TASK_ID='retrain_model' AIRFLOW_CTX_EXECUTION_DATE='2025-06-22T00:00:00+00:00' AIRFLOW_CTX_TRY_NUMBER='1' AIRFLOW_CTX_DAG_RUN_ID='scheduled__2025-06-22T00:00:00+00:00'
[2025-07-05T23:26:15.784+0000] {taskinstance.py:430} INFO - ::endgroup::
[2025-07-05T23:26:15.824+0000] {logging_mixin.py:188} INFO - [INFO] Found latest timestamp: 2025-07-04-15
[2025-07-05T23:26:15.825+0000] {logging_mixin.py:188} INFO - [INFO] Starting model training...
[2025-07-05T23:26:16.311+0000] {logging_mixin.py:188} WARNING - 2025/07/05 23:26:16 WARNING mlflow.utils.git_utils: Failed to import Git (the Git executable is probably not on your PATH), so Git SHA is not available. Error: Failed to initialize: Bad git executable.
The git executable must be specified in one of the following ways:
    - be included in your $PATH
    - be set via $GIT_PYTHON_GIT_EXECUTABLE
    - explicitly set via git.refresh(<full-path-to-git-executable>)

All git commands will error until this is rectified.

This initial message can be silenced or aggravated in the future by setting the
$GIT_PYTHON_REFRESH environment variable. Use one of the following values:
    - quiet|q|silence|s|silent|none|n|0: for no message or exception
    - warn|w|warning|log|l|1: for a warning message (logging level CRITICAL, displayed by default)
    - error|e|exception|raise|r|2: for a raised exception

Example:
    export GIT_PYTHON_REFRESH=quiet
[2025-07-05T23:26:17.705+0000] {logging_mixin.py:188} INFO - 🏃 View run carefree-skunk-834 at: http://mlflow-server:5000/#/experiments/1/runs/9f7d627b841943fbb15d53bd3325de9a
[2025-07-05T23:26:17.707+0000] {logging_mixin.py:188} INFO - 🧪 View experiment at: http://mlflow-server:5000/#/experiments/1
[2025-07-05T23:26:17.725+0000] {taskinstance.py:441} INFO - ::group::Post task execution logs
[2025-07-05T23:26:17.726+0000] {taskinstance.py:2905} ERROR - Task failed with exception
Traceback (most recent call last):
  File "/home/airflow/.local/lib/python3.12/site-packages/airflow/models/taskinstance.py", line 465, in _execute_task
    result = _execute_callable(context=context, **execute_callable_kwargs)
             ^^^^^^^^^^^^^^^^^^^^^^^^^^^^^^^^^^^^^^^^^^^^^^^^^^^^^^^^^^^^^
  File "/home/airflow/.local/lib/python3.12/site-packages/airflow/models/taskinstance.py", line 432, in _execute_callable
    return execute_callable(context=context, **execute_callable_kwargs)
           ^^^^^^^^^^^^^^^^^^^^^^^^^^^^^^^^^^^^^^^^^^^^^^^^^^^^^^^^^^^^
  File "/home/airflow/.local/lib/python3.12/site-packages/airflow/models/baseoperator.py", line 400, in wrapper
    return func(self, *args, **kwargs)
           ^^^^^^^^^^^^^^^^^^^^^^^^^^^
  File "/home/airflow/.local/lib/python3.12/site-packages/airflow/operators/python.py", line 235, in execute
    return_value = self.execute_callable()
                   ^^^^^^^^^^^^^^^^^^^^^^^
  File "/home/airflow/.local/lib/python3.12/site-packages/airflow/operators/python.py", line 252, in execute_callable
    return self.python_callable(*self.op_args, **self.op_kwargs)
           ^^^^^^^^^^^^^^^^^^^^^^^^^^^^^^^^^^^^^^^^^^^^^^^^^^^^^
  File "/opt/airflow/github_pipeline/train_model.py", line 100, in main
    run_training(latest_ts)
  File "/opt/airflow/github_pipeline/train_model.py", line 60, in run_training
    mlflow.log_artifact(str(model_file))
  File "/home/airflow/.local/lib/python3.12/site-packages/mlflow/tracking/fluent.py", line 1404, in log_artifact
    MlflowClient().log_artifact(run_id, local_path, artifact_path)
  File "/home/airflow/.local/lib/python3.12/site-packages/mlflow/tracking/client.py", line 2448, in log_artifact
    self._tracking_client.log_artifact(run_id, local_path, artifact_path)
  File "/home/airflow/.local/lib/python3.12/site-packages/mlflow/tracking/_tracking_service/client.py", line 639, in log_artifact
    artifact_repo.log_artifact(local_path, artifact_path)
  File "/home/airflow/.local/lib/python3.12/site-packages/mlflow/store/artifact/local_artifact_repo.py", line 43, in log_artifact
    mkdir(artifact_dir)
  File "/home/airflow/.local/lib/python3.12/site-packages/mlflow/utils/file_utils.py", line 209, in mkdir
    raise e
  File "/home/airflow/.local/lib/python3.12/site-packages/mlflow/utils/file_utils.py", line 206, in mkdir
    os.makedirs(target, exist_ok=True)
  File "<frozen os>", line 215, in makedirs
  File "<frozen os>", line 215, in makedirs
  File "<frozen os>", line 215, in makedirs
  File "<frozen os>", line 225, in makedirs
PermissionError: [Errno 13] Permission denied: '/mlflow-artifacts'
[2025-07-05T23:26:17.740+0000] {taskinstance.py:1206} INFO - Marking task as UP_FOR_RETRY. dag_id=weekly_model_retraining, task_id=retrain_model, run_id=scheduled__2025-06-22T00:00:00+00:00, execution_date=20250622T000000, start_date=20250705T232615, end_date=20250705T232617
[2025-07-05T23:26:17.763+0000] {standard_task_runner.py:110} ERROR - Failed to execute job 12 for task retrain_model ([Errno 13] Permission denied: '/mlflow-artifacts'; 298)
[2025-07-05T23:26:17.834+0000] {local_task_job_runner.py:240} INFO - Task exited with return code 1
[2025-07-05T23:26:17.862+0000] {taskinstance.py:3498} INFO - 0 downstream tasks scheduled from follow-on schedule check
[2025-07-05T23:26:17.864+0000] {local_task_job_runner.py:222} INFO - ::endgroup::
[2025-07-05T23:32:42.886+0000] {local_task_job_runner.py:120} INFO - ::group::Pre task execution logs
[2025-07-05T23:32:42.975+0000] {taskinstance.py:2076} INFO - Dependencies all met for dep_context=non-requeueable deps ti=<TaskInstance: weekly_model_retraining.retrain_model scheduled__2025-06-22T00:00:00+00:00 [queued]>
[2025-07-05T23:32:42.989+0000] {taskinstance.py:2076} INFO - Dependencies all met for dep_context=requeueable deps ti=<TaskInstance: weekly_model_retraining.retrain_model scheduled__2025-06-22T00:00:00+00:00 [queued]>
[2025-07-05T23:32:42.990+0000] {taskinstance.py:2306} INFO - Starting attempt 1 of 2
[2025-07-05T23:32:43.003+0000] {taskinstance.py:2330} INFO - Executing <Task(PythonOperator): retrain_model> on 2025-06-22 00:00:00+00:00
[2025-07-05T23:32:43.029+0000] {logging_mixin.py:188} WARNING - /home/***/.local/lib/python3.12/site-packages/***/task/task_runner/standard_task_runner.py:61 DeprecationWarning: This process (pid=190) is multi-threaded, use of fork() may lead to deadlocks in the child.
[2025-07-05T23:32:43.030+0000] {standard_task_runner.py:63} INFO - Started process 202 to run task
[2025-07-05T23:32:43.033+0000] {standard_task_runner.py:90} INFO - Running: ['***', 'tasks', 'run', 'weekly_model_retraining', 'retrain_model', 'scheduled__2025-06-22T00:00:00+00:00', '--job-id', '2', '--raw', '--subdir', 'DAGS_FOLDER/retraining_dag.py', '--cfg-path', '/tmp/tmprkuu3o5s']
[2025-07-05T23:32:43.035+0000] {standard_task_runner.py:91} INFO - Job 2: Subtask retrain_model
[2025-07-05T23:32:43.062+0000] {logging_mixin.py:188} WARNING - /home/***/.local/lib/python3.12/site-packages/***/settings.py:195 DeprecationWarning: The sql_alchemy_conn option in [core] has been moved to the sql_alchemy_conn option in [database] - the old setting has been used, but please update your config.
[2025-07-05T23:32:43.115+0000] {task_command.py:426} INFO - Running <TaskInstance: weekly_model_retraining.retrain_model scheduled__2025-06-22T00:00:00+00:00 [running]> on host e30568aca77e
[2025-07-05T23:32:43.322+0000] {taskinstance.py:2648} INFO - Exporting env vars: AIRFLOW_CTX_DAG_OWNER='rajat' AIRFLOW_CTX_DAG_ID='weekly_model_retraining' AIRFLOW_CTX_TASK_ID='retrain_model' AIRFLOW_CTX_EXECUTION_DATE='2025-06-22T00:00:00+00:00' AIRFLOW_CTX_TRY_NUMBER='1' AIRFLOW_CTX_DAG_RUN_ID='scheduled__2025-06-22T00:00:00+00:00'
[2025-07-05T23:32:43.326+0000] {taskinstance.py:430} INFO - ::endgroup::
[2025-07-05T23:32:43.399+0000] {logging_mixin.py:188} INFO - [INFO] Found latest timestamp: 2025-07-04-15
[2025-07-05T23:32:43.400+0000] {logging_mixin.py:188} INFO - [INFO] Starting model training...
[2025-07-05T23:32:43.874+0000] {logging_mixin.py:188} WARNING - 2025/07/05 23:32:43 WARNING mlflow.utils.git_utils: Failed to import Git (the Git executable is probably not on your PATH), so Git SHA is not available. Error: Failed to initialize: Bad git executable.
The git executable must be specified in one of the following ways:
    - be included in your $PATH
    - be set via $GIT_PYTHON_GIT_EXECUTABLE
    - explicitly set via git.refresh(<full-path-to-git-executable>)

All git commands will error until this is rectified.

This initial message can be silenced or aggravated in the future by setting the
$GIT_PYTHON_REFRESH environment variable. Use one of the following values:
    - quiet|q|silence|s|silent|none|n|0: for no message or exception
    - warn|w|warning|log|l|1: for a warning message (logging level CRITICAL, displayed by default)
    - error|e|exception|raise|r|2: for a raised exception

Example:
    export GIT_PYTHON_REFRESH=quiet
[2025-07-05T23:32:45.583+0000] {logging_mixin.py:188} INFO - 🏃 View run thoughtful-lynx-327 at: http://mlflow-server:5000/#/experiments/1/runs/d1a7ee78c4964ce39ba9f781377e317c
[2025-07-05T23:32:45.583+0000] {logging_mixin.py:188} INFO - 🧪 View experiment at: http://mlflow-server:5000/#/experiments/1
[2025-07-05T23:32:45.626+0000] {taskinstance.py:441} INFO - ::group::Post task execution logs
[2025-07-05T23:32:45.626+0000] {taskinstance.py:2905} ERROR - Task failed with exception
Traceback (most recent call last):
  File "/home/airflow/.local/lib/python3.12/site-packages/airflow/models/taskinstance.py", line 465, in _execute_task
    result = _execute_callable(context=context, **execute_callable_kwargs)
             ^^^^^^^^^^^^^^^^^^^^^^^^^^^^^^^^^^^^^^^^^^^^^^^^^^^^^^^^^^^^^
  File "/home/airflow/.local/lib/python3.12/site-packages/airflow/models/taskinstance.py", line 432, in _execute_callable
    return execute_callable(context=context, **execute_callable_kwargs)
           ^^^^^^^^^^^^^^^^^^^^^^^^^^^^^^^^^^^^^^^^^^^^^^^^^^^^^^^^^^^^
  File "/home/airflow/.local/lib/python3.12/site-packages/airflow/models/baseoperator.py", line 400, in wrapper
    return func(self, *args, **kwargs)
           ^^^^^^^^^^^^^^^^^^^^^^^^^^^
  File "/home/airflow/.local/lib/python3.12/site-packages/airflow/operators/python.py", line 235, in execute
    return_value = self.execute_callable()
                   ^^^^^^^^^^^^^^^^^^^^^^^
  File "/home/airflow/.local/lib/python3.12/site-packages/airflow/operators/python.py", line 252, in execute_callable
    return self.python_callable(*self.op_args, **self.op_kwargs)
           ^^^^^^^^^^^^^^^^^^^^^^^^^^^^^^^^^^^^^^^^^^^^^^^^^^^^^
  File "/opt/airflow/github_pipeline/train_model.py", line 100, in main
    run_training(latest_ts)
  File "/opt/airflow/github_pipeline/train_model.py", line 60, in run_training
    mlflow.log_artifact(str(model_file))
  File "/home/airflow/.local/lib/python3.12/site-packages/mlflow/tracking/fluent.py", line 1404, in log_artifact
    MlflowClient().log_artifact(run_id, local_path, artifact_path)
  File "/home/airflow/.local/lib/python3.12/site-packages/mlflow/tracking/client.py", line 2448, in log_artifact
    self._tracking_client.log_artifact(run_id, local_path, artifact_path)
  File "/home/airflow/.local/lib/python3.12/site-packages/mlflow/tracking/_tracking_service/client.py", line 639, in log_artifact
    artifact_repo.log_artifact(local_path, artifact_path)
  File "/home/airflow/.local/lib/python3.12/site-packages/mlflow/store/artifact/local_artifact_repo.py", line 43, in log_artifact
    mkdir(artifact_dir)
  File "/home/airflow/.local/lib/python3.12/site-packages/mlflow/utils/file_utils.py", line 209, in mkdir
    raise e
  File "/home/airflow/.local/lib/python3.12/site-packages/mlflow/utils/file_utils.py", line 206, in mkdir
    os.makedirs(target, exist_ok=True)
  File "<frozen os>", line 215, in makedirs
  File "<frozen os>", line 215, in makedirs
  File "<frozen os>", line 215, in makedirs
  File "<frozen os>", line 225, in makedirs
PermissionError: [Errno 13] Permission denied: '/mlflow-artifacts'
[2025-07-05T23:32:45.667+0000] {taskinstance.py:1206} INFO - Marking task as UP_FOR_RETRY. dag_id=weekly_model_retraining, task_id=retrain_model, run_id=scheduled__2025-06-22T00:00:00+00:00, execution_date=20250622T000000, start_date=20250705T233242, end_date=20250705T233245
[2025-07-05T23:32:45.701+0000] {standard_task_runner.py:110} ERROR - Failed to execute job 2 for task retrain_model ([Errno 13] Permission denied: '/mlflow-artifacts'; 202)
[2025-07-05T23:32:45.761+0000] {local_task_job_runner.py:240} INFO - Task exited with return code 1
[2025-07-05T23:32:45.786+0000] {taskinstance.py:3498} INFO - 0 downstream tasks scheduled from follow-on schedule check
[2025-07-05T23:32:45.789+0000] {local_task_job_runner.py:222} INFO - ::endgroup::
