[2025-07-09T21:09:06.357+0000] {local_task_job_runner.py:120} INFO - ::group::Pre task execution logs
[2025-07-09T21:09:06.376+0000] {taskinstance.py:2076} INFO - Dependencies all met for dep_context=non-requeueable deps ti=<TaskInstance: weekly_model_retraining.retrain_model manual__2025-07-09T21:09:02.648058+00:00 [queued]>
[2025-07-09T21:09:06.382+0000] {taskinstance.py:2076} INFO - Dependencies all met for dep_context=requeueable deps ti=<TaskInstance: weekly_model_retraining.retrain_model manual__2025-07-09T21:09:02.648058+00:00 [queued]>
[2025-07-09T21:09:06.382+0000] {taskinstance.py:2306} INFO - Starting attempt 1 of 2
[2025-07-09T21:09:06.397+0000] {taskinstance.py:2330} INFO - Executing <Task(PythonOperator): retrain_model> on 2025-07-09 21:09:02.648058+00:00
[2025-07-09T21:09:06.410+0000] {logging_mixin.py:188} WARNING - /home/***/.local/lib/python3.12/site-packages/***/task/task_runner/standard_task_runner.py:61 DeprecationWarning: This process (pid=202) is multi-threaded, use of fork() may lead to deadlocks in the child.
[2025-07-09T21:09:06.411+0000] {standard_task_runner.py:63} INFO - Started process 208 to run task
[2025-07-09T21:09:06.413+0000] {standard_task_runner.py:90} INFO - Running: ['***', 'tasks', 'run', 'weekly_model_retraining', 'retrain_model', 'manual__2025-07-09T21:09:02.648058+00:00', '--job-id', '92', '--raw', '--subdir', 'DAGS_FOLDER/retraining_dag.py', '--cfg-path', '/tmp/tmpczxm79vr']
[2025-07-09T21:09:06.415+0000] {standard_task_runner.py:91} INFO - Job 92: Subtask retrain_model
[2025-07-09T21:09:06.427+0000] {logging_mixin.py:188} WARNING - /home/***/.local/lib/python3.12/site-packages/***/settings.py:195 DeprecationWarning: The sql_alchemy_conn option in [core] has been moved to the sql_alchemy_conn option in [database] - the old setting has been used, but please update your config.
[2025-07-09T21:09:06.451+0000] {task_command.py:426} INFO - Running <TaskInstance: weekly_model_retraining.retrain_model manual__2025-07-09T21:09:02.648058+00:00 [running]> on host 7a380272068f
[2025-07-09T21:09:06.523+0000] {taskinstance.py:2648} INFO - Exporting env vars: AIRFLOW_CTX_DAG_OWNER='rajat' AIRFLOW_CTX_DAG_ID='weekly_model_retraining' AIRFLOW_CTX_TASK_ID='retrain_model' AIRFLOW_CTX_EXECUTION_DATE='2025-07-09T21:09:02.648058+00:00' AIRFLOW_CTX_TRY_NUMBER='1' AIRFLOW_CTX_DAG_RUN_ID='manual__2025-07-09T21:09:02.648058+00:00'
[2025-07-09T21:09:06.524+0000] {taskinstance.py:430} INFO - ::endgroup::
[2025-07-09T21:09:06.565+0000] {credentials.py:567} INFO - Found credentials in environment variables.
[2025-07-09T21:09:07.082+0000] {logging_mixin.py:188} INFO - [INFO] Searching for files on S3...
[2025-07-09T21:09:07.084+0000] {logging_mixin.py:188} INFO - [INFO] Found latest timestamp: 2025-07-08-15
[2025-07-09T21:09:07.085+0000] {logging_mixin.py:188} INFO - [INFO] Starting model training...
[2025-07-09T21:09:07.286+0000] {credentials.py:567} INFO - Found credentials in environment variables.
[2025-07-09T21:09:08.844+0000] {logging_mixin.py:188} WARNING - 2025/07/09 21:09:08 WARNING mlflow.utils.git_utils: Failed to import Git (the Git executable is probably not on your PATH), so Git SHA is not available. Error: Failed to initialize: Bad git executable.
The git executable must be specified in one of the following ways:
    - be included in your $PATH
    - be set via $GIT_PYTHON_GIT_EXECUTABLE
    - explicitly set via git.refresh(<full-path-to-git-executable>)

All git commands will error until this is rectified.

This initial message can be silenced or aggravated in the future by setting the
$GIT_PYTHON_REFRESH environment variable. Use one of the following values:
    - quiet|q|silence|s|silent|none|n|0: for no message or exception
    - warn|w|warning|log|l|1: for a warning message (logging level CRITICAL, displayed by default)
    - error|e|exception|raise|r|2: for a raised exception

Example:
    export GIT_PYTHON_REFRESH=quiet
[2025-07-09T21:09:10.408+0000] {logging_mixin.py:188} WARNING - 2025/07/09 21:09:10 WARNING mlflow.models.model: `artifact_path` is deprecated. Please use `name` instead.
[2025-07-09T21:09:16.451+0000] {logging_mixin.py:188} WARNING - 2025/07/09 21:09:16 WARNING mlflow.models.model: Model logged without a signature and input example. Please set `input_example` parameter when logging the model to auto infer the model signature.
[2025-07-09T21:09:16.706+0000] {logging_mixin.py:188} WARNING - Registered model 'github-anomaly-isolation-forest' already exists. Creating a new version of this model...
[2025-07-09T21:09:16.848+0000] {logging_mixin.py:188} WARNING - 2025/07/09 21:09:16 INFO mlflow.store.model_registry.abstract_store: Waiting up to 300 seconds for model version to finish creation. Model name: github-anomaly-isolation-forest, version 4
[2025-07-09T21:09:16.849+0000] {logging_mixin.py:188} WARNING - Created version '4' of model 'github-anomaly-isolation-forest'.
[2025-07-09T21:09:16.983+0000] {logging_mixin.py:188} INFO - üèÉ View run skillful-hound-81 at: http://mlflow-server:5000/#/experiments/1/runs/4b3bfdddd0ec49eea7b4dc3b8e880193
[2025-07-09T21:09:16.983+0000] {logging_mixin.py:188} INFO - üß™ View experiment at: http://mlflow-server:5000/#/experiments/1
[2025-07-09T21:09:17.006+0000] {taskinstance.py:441} INFO - ::group::Post task execution logs
[2025-07-09T21:09:17.006+0000] {taskinstance.py:2905} ERROR - Task failed with exception
Traceback (most recent call last):
  File "/home/airflow/.local/lib/python3.12/site-packages/airflow/models/taskinstance.py", line 465, in _execute_task
    result = _execute_callable(context=context, **execute_callable_kwargs)
             ^^^^^^^^^^^^^^^^^^^^^^^^^^^^^^^^^^^^^^^^^^^^^^^^^^^^^^^^^^^^^
  File "/home/airflow/.local/lib/python3.12/site-packages/airflow/models/taskinstance.py", line 432, in _execute_callable
    return execute_callable(context=context, **execute_callable_kwargs)
           ^^^^^^^^^^^^^^^^^^^^^^^^^^^^^^^^^^^^^^^^^^^^^^^^^^^^^^^^^^^^
  File "/home/airflow/.local/lib/python3.12/site-packages/airflow/models/baseoperator.py", line 400, in wrapper
    return func(self, *args, **kwargs)
           ^^^^^^^^^^^^^^^^^^^^^^^^^^^
  File "/home/airflow/.local/lib/python3.12/site-packages/airflow/operators/python.py", line 235, in execute
    return_value = self.execute_callable()
                   ^^^^^^^^^^^^^^^^^^^^^^^
  File "/home/airflow/.local/lib/python3.12/site-packages/airflow/operators/python.py", line 252, in execute_callable
    return self.python_callable(*self.op_args, **self.op_kwargs)
           ^^^^^^^^^^^^^^^^^^^^^^^^^^^^^^^^^^^^^^^^^^^^^^^^^^^^^
  File "/opt/airflow/github_pipeline/train_model.py", line 158, in main
    run_training(latest_ts)
  File "/opt/airflow/github_pipeline/train_model.py", line 111, in run_training
    write_parquet(df, output_file)
  File "/opt/airflow/github_pipeline/utils/aws_utils.py", line 29, in write_parquet
    fs.put(tmp.name, get_s3_path(relative_path))
  File "/home/airflow/.local/lib/python3.12/site-packages/fsspec/asyn.py", line 118, in wrapper
    return sync(self.loop, func, *args, **kwargs)
                ^^^^^^^^^
  File "/home/airflow/.local/lib/python3.12/site-packages/fsspec/asyn.py", line 340, in loop
    raise RuntimeError("This class is not fork-safe")
RuntimeError: This class is not fork-safe
[2025-07-09T21:09:17.018+0000] {taskinstance.py:1206} INFO - Marking task as UP_FOR_RETRY. dag_id=weekly_model_retraining, task_id=retrain_model, run_id=manual__2025-07-09T21:09:02.648058+00:00, execution_date=20250709T210902, start_date=20250709T210906, end_date=20250709T210917
[2025-07-09T21:09:17.041+0000] {standard_task_runner.py:110} ERROR - Failed to execute job 92 for task retrain_model (This class is not fork-safe; 208)
[2025-07-09T21:09:17.096+0000] {local_task_job_runner.py:240} INFO - Task exited with return code 1
[2025-07-09T21:09:17.107+0000] {taskinstance.py:3498} INFO - 0 downstream tasks scheduled from follow-on schedule check
[2025-07-09T21:09:17.108+0000] {local_task_job_runner.py:222} INFO - ::endgroup::
