[2025-07-09T21:21:40.694+0000] {local_task_job_runner.py:120} INFO - ::group::Pre task execution logs
[2025-07-09T21:21:40.726+0000] {taskinstance.py:2076} INFO - Dependencies all met for dep_context=non-requeueable deps ti=<TaskInstance: daily_monitoring_dag.run_drift_monitoring manual__2025-07-09T21:19:25.701572+00:00 [queued]>
[2025-07-09T21:21:40.734+0000] {taskinstance.py:2076} INFO - Dependencies all met for dep_context=requeueable deps ti=<TaskInstance: daily_monitoring_dag.run_drift_monitoring manual__2025-07-09T21:19:25.701572+00:00 [queued]>
[2025-07-09T21:21:40.734+0000] {taskinstance.py:2306} INFO - Starting attempt 2 of 2
[2025-07-09T21:21:40.744+0000] {taskinstance.py:2330} INFO - Executing <Task(PythonOperator): run_drift_monitoring> on 2025-07-09 21:19:25.701572+00:00
[2025-07-09T21:21:40.756+0000] {logging_mixin.py:188} WARNING - /home/***/.local/lib/python3.12/site-packages/***/task/task_runner/standard_task_runner.py:61 DeprecationWarning: This process (pid=312) is multi-threaded, use of fork() may lead to deadlocks in the child.
[2025-07-09T21:21:40.757+0000] {standard_task_runner.py:63} INFO - Started process 322 to run task
[2025-07-09T21:21:40.757+0000] {standard_task_runner.py:90} INFO - Running: ['***', 'tasks', 'run', 'daily_monitoring_dag', 'run_drift_monitoring', 'manual__2025-07-09T21:19:25.701572+00:00', '--job-id', '103', '--raw', '--subdir', 'DAGS_FOLDER/daily_monitoring_dag.py', '--cfg-path', '/tmp/tmpjwmy8q3g']
[2025-07-09T21:21:40.760+0000] {standard_task_runner.py:91} INFO - Job 103: Subtask run_drift_monitoring
[2025-07-09T21:21:40.771+0000] {logging_mixin.py:188} WARNING - /home/***/.local/lib/python3.12/site-packages/***/settings.py:195 DeprecationWarning: The sql_alchemy_conn option in [core] has been moved to the sql_alchemy_conn option in [database] - the old setting has been used, but please update your config.
[2025-07-09T21:21:40.793+0000] {task_command.py:426} INFO - Running <TaskInstance: daily_monitoring_dag.run_drift_monitoring manual__2025-07-09T21:19:25.701572+00:00 [running]> on host 6f7c25b7640a
[2025-07-09T21:21:40.872+0000] {taskinstance.py:2648} INFO - Exporting env vars: AIRFLOW_CTX_DAG_OWNER='rajat' AIRFLOW_CTX_DAG_ID='daily_monitoring_dag' AIRFLOW_CTX_TASK_ID='run_drift_monitoring' AIRFLOW_CTX_EXECUTION_DATE='2025-07-09T21:19:25.701572+00:00' AIRFLOW_CTX_TRY_NUMBER='2' AIRFLOW_CTX_DAG_RUN_ID='manual__2025-07-09T21:19:25.701572+00:00'
[2025-07-09T21:21:40.873+0000] {taskinstance.py:430} INFO - ::endgroup::
[2025-07-09T21:21:40.883+0000] {taskinstance.py:441} INFO - ::group::Post task execution logs
[2025-07-09T21:21:40.884+0000] {taskinstance.py:2905} ERROR - Task failed with exception
Traceback (most recent call last):
  File "/home/airflow/.local/lib/python3.12/site-packages/airflow/models/taskinstance.py", line 465, in _execute_task
    result = _execute_callable(context=context, **execute_callable_kwargs)
             ^^^^^^^^^^^^^^^^^^^^^^^^^^^^^^^^^^^^^^^^^^^^^^^^^^^^^^^^^^^^^
  File "/home/airflow/.local/lib/python3.12/site-packages/airflow/models/taskinstance.py", line 432, in _execute_callable
    return execute_callable(context=context, **execute_callable_kwargs)
           ^^^^^^^^^^^^^^^^^^^^^^^^^^^^^^^^^^^^^^^^^^^^^^^^^^^^^^^^^^^^
  File "/home/airflow/.local/lib/python3.12/site-packages/airflow/models/baseoperator.py", line 400, in wrapper
    return func(self, *args, **kwargs)
           ^^^^^^^^^^^^^^^^^^^^^^^^^^^
  File "/home/airflow/.local/lib/python3.12/site-packages/airflow/operators/python.py", line 235, in execute
    return_value = self.execute_callable()
                   ^^^^^^^^^^^^^^^^^^^^^^^
  File "/home/airflow/.local/lib/python3.12/site-packages/airflow/operators/python.py", line 252, in execute_callable
    return self.python_callable(*self.op_args, **self.op_kwargs)
           ^^^^^^^^^^^^^^^^^^^^^^^^^^^^^^^^^^^^^^^^^^^^^^^^^^^^^
  File "/opt/airflow/dags/daily_monitoring_dag.py", line 69, in run_monitoring_wrapper
    ref_ts, cur_ts = get_two_latest_timestamps()
                     ^^^^^^^^^^^^^^^^^^^^^^^^^^^
  File "/opt/airflow/dags/daily_monitoring_dag.py", line 61, in get_two_latest_timestamps
    raise RuntimeError("[ERROR] Need at least two feature files for drift monitoring.")
RuntimeError: [ERROR] Need at least two feature files for drift monitoring.
[2025-07-09T21:21:40.891+0000] {taskinstance.py:1206} INFO - Marking task as FAILED. dag_id=daily_monitoring_dag, task_id=run_drift_monitoring, run_id=manual__2025-07-09T21:19:25.701572+00:00, execution_date=20250709T211925, start_date=20250709T212140, end_date=20250709T212140
[2025-07-09T21:21:40.898+0000] {standard_task_runner.py:110} ERROR - Failed to execute job 103 for task run_drift_monitoring ([ERROR] Need at least two feature files for drift monitoring.; 322)
[2025-07-09T21:21:40.932+0000] {local_task_job_runner.py:240} INFO - Task exited with return code 1
[2025-07-09T21:21:40.944+0000] {taskinstance.py:3498} INFO - 0 downstream tasks scheduled from follow-on schedule check
[2025-07-09T21:21:40.945+0000] {local_task_job_runner.py:222} INFO - ::endgroup::
