[2025-07-04T14:37:49.370+0000] {local_task_job_runner.py:120} INFO - ::group::Pre task execution logs
[2025-07-04T14:37:49.404+0000] {taskinstance.py:2076} INFO - Dependencies all met for dep_context=non-requeueable deps ti=<TaskInstance: daily_monitoring_dag.run_drift_monitoring scheduled__2025-07-03T00:00:00+00:00 [queued]>
[2025-07-04T14:37:49.416+0000] {taskinstance.py:2076} INFO - Dependencies all met for dep_context=requeueable deps ti=<TaskInstance: daily_monitoring_dag.run_drift_monitoring scheduled__2025-07-03T00:00:00+00:00 [queued]>
[2025-07-04T14:37:49.417+0000] {taskinstance.py:2306} INFO - Starting attempt 2 of 2
[2025-07-04T14:37:49.430+0000] {taskinstance.py:2330} INFO - Executing <Task(PythonOperator): run_drift_monitoring> on 2025-07-03 00:00:00+00:00
[2025-07-04T14:37:49.448+0000] {logging_mixin.py:188} WARNING - /home/***/.local/lib/python3.12/site-packages/***/task/task_runner/standard_task_runner.py:61 DeprecationWarning: This process (pid=301) is multi-threaded, use of fork() may lead to deadlocks in the child.
[2025-07-04T14:37:49.452+0000] {standard_task_runner.py:63} INFO - Started process 308 to run task
[2025-07-04T14:37:49.450+0000] {standard_task_runner.py:90} INFO - Running: ['***', 'tasks', 'run', 'daily_monitoring_dag', 'run_drift_monitoring', 'scheduled__2025-07-03T00:00:00+00:00', '--job-id', '9', '--raw', '--subdir', 'DAGS_FOLDER/monitoring_dag.py', '--cfg-path', '/tmp/tmpjzyj0fuq']
[2025-07-04T14:37:49.454+0000] {standard_task_runner.py:91} INFO - Job 9: Subtask run_drift_monitoring
[2025-07-04T14:37:49.470+0000] {logging_mixin.py:188} WARNING - /home/***/.local/lib/python3.12/site-packages/***/settings.py:195 DeprecationWarning: The sql_alchemy_conn option in [core] has been moved to the sql_alchemy_conn option in [database] - the old setting has been used, but please update your config.
[2025-07-04T14:37:49.503+0000] {task_command.py:426} INFO - Running <TaskInstance: daily_monitoring_dag.run_drift_monitoring scheduled__2025-07-03T00:00:00+00:00 [running]> on host a4cd470c7ef1
[2025-07-04T14:37:49.586+0000] {taskinstance.py:2648} INFO - Exporting env vars: AIRFLOW_CTX_DAG_OWNER='***' AIRFLOW_CTX_DAG_ID='daily_monitoring_dag' AIRFLOW_CTX_TASK_ID='run_drift_monitoring' AIRFLOW_CTX_EXECUTION_DATE='2025-07-03T00:00:00+00:00' AIRFLOW_CTX_TRY_NUMBER='2' AIRFLOW_CTX_DAG_RUN_ID='scheduled__2025-07-03T00:00:00+00:00'
[2025-07-04T14:37:49.587+0000] {taskinstance.py:430} INFO - ::endgroup::
[2025-07-04T14:37:49.598+0000] {taskinstance.py:441} INFO - ::group::Post task execution logs
[2025-07-04T14:37:49.599+0000] {taskinstance.py:2905} ERROR - Task failed with exception
Traceback (most recent call last):
  File "/home/airflow/.local/lib/python3.12/site-packages/airflow/models/taskinstance.py", line 465, in _execute_task
    result = _execute_callable(context=context, **execute_callable_kwargs)
             ^^^^^^^^^^^^^^^^^^^^^^^^^^^^^^^^^^^^^^^^^^^^^^^^^^^^^^^^^^^^^
  File "/home/airflow/.local/lib/python3.12/site-packages/airflow/models/taskinstance.py", line 432, in _execute_callable
    return execute_callable(context=context, **execute_callable_kwargs)
           ^^^^^^^^^^^^^^^^^^^^^^^^^^^^^^^^^^^^^^^^^^^^^^^^^^^^^^^^^^^^
  File "/home/airflow/.local/lib/python3.12/site-packages/airflow/models/baseoperator.py", line 400, in wrapper
    return func(self, *args, **kwargs)
           ^^^^^^^^^^^^^^^^^^^^^^^^^^^
  File "/home/airflow/.local/lib/python3.12/site-packages/airflow/operators/python.py", line 235, in execute
    return_value = self.execute_callable()
                   ^^^^^^^^^^^^^^^^^^^^^^^
  File "/home/airflow/.local/lib/python3.12/site-packages/airflow/operators/python.py", line 252, in execute_callable
    return self.python_callable(*self.op_args, **self.op_kwargs)
           ^^^^^^^^^^^^^^^^^^^^^^^^^^^^^^^^^^^^^^^^^^^^^^^^^^^^^
  File "/opt/airflow/dags/monitoring_dag.py", line 27, in run_monitoring_wrapper
    run_monitoring(reference_ts=reference_ts, current_ts=current_ts)
  File "/opt/airflow/github_pipeline/monitor.py", line 24, in run_monitoring
    raise FileNotFoundError(f"[ERROR] Reference file not found: {ref_file}")
FileNotFoundError: [ERROR] Reference file not found: data/features/actor_features_2025-07-03-15.parquet
[2025-07-04T14:37:49.606+0000] {taskinstance.py:1206} INFO - Marking task as FAILED. dag_id=daily_monitoring_dag, task_id=run_drift_monitoring, run_id=scheduled__2025-07-03T00:00:00+00:00, execution_date=20250703T000000, start_date=20250704T143749, end_date=20250704T143749
[2025-07-04T14:37:49.614+0000] {standard_task_runner.py:110} ERROR - Failed to execute job 9 for task run_drift_monitoring ([ERROR] Reference file not found: data/features/actor_features_2025-07-03-15.parquet; 308)
[2025-07-04T14:37:49.629+0000] {local_task_job_runner.py:240} INFO - Task exited with return code 1
[2025-07-04T14:37:49.642+0000] {taskinstance.py:3498} INFO - 0 downstream tasks scheduled from follow-on schedule check
[2025-07-04T14:37:49.643+0000] {local_task_job_runner.py:222} INFO - ::endgroup::
[2025-07-04T14:47:58.160+0000] {local_task_job_runner.py:120} INFO - ::group::Pre task execution logs
[2025-07-04T14:47:58.182+0000] {taskinstance.py:2076} INFO - Dependencies all met for dep_context=non-requeueable deps ti=<TaskInstance: daily_monitoring_dag.run_drift_monitoring scheduled__2025-07-03T00:00:00+00:00 [queued]>
[2025-07-04T14:47:58.189+0000] {taskinstance.py:2076} INFO - Dependencies all met for dep_context=requeueable deps ti=<TaskInstance: daily_monitoring_dag.run_drift_monitoring scheduled__2025-07-03T00:00:00+00:00 [queued]>
[2025-07-04T14:47:58.190+0000] {taskinstance.py:2306} INFO - Starting attempt 2 of 2
[2025-07-04T14:47:58.199+0000] {taskinstance.py:2330} INFO - Executing <Task(PythonOperator): run_drift_monitoring> on 2025-07-03 00:00:00+00:00
[2025-07-04T14:47:58.208+0000] {logging_mixin.py:188} WARNING - /home/***/.local/lib/python3.12/site-packages/***/task/task_runner/standard_task_runner.py:61 DeprecationWarning: This process (pid=387) is multi-threaded, use of fork() may lead to deadlocks in the child.
[2025-07-04T14:47:58.210+0000] {standard_task_runner.py:63} INFO - Started process 391 to run task
[2025-07-04T14:47:58.209+0000] {standard_task_runner.py:90} INFO - Running: ['***', 'tasks', 'run', 'daily_monitoring_dag', 'run_drift_monitoring', 'scheduled__2025-07-03T00:00:00+00:00', '--job-id', '9', '--raw', '--subdir', 'DAGS_FOLDER/monitoring_dag.py', '--cfg-path', '/tmp/tmp7q9t8e60']
[2025-07-04T14:47:58.211+0000] {standard_task_runner.py:91} INFO - Job 9: Subtask run_drift_monitoring
[2025-07-04T14:47:58.222+0000] {logging_mixin.py:188} WARNING - /home/***/.local/lib/python3.12/site-packages/***/settings.py:195 DeprecationWarning: The sql_alchemy_conn option in [core] has been moved to the sql_alchemy_conn option in [database] - the old setting has been used, but please update your config.
[2025-07-04T14:47:58.249+0000] {task_command.py:426} INFO - Running <TaskInstance: daily_monitoring_dag.run_drift_monitoring scheduled__2025-07-03T00:00:00+00:00 [running]> on host e8e8a486d025
[2025-07-04T14:47:58.308+0000] {taskinstance.py:2648} INFO - Exporting env vars: AIRFLOW_CTX_DAG_OWNER='***' AIRFLOW_CTX_DAG_ID='daily_monitoring_dag' AIRFLOW_CTX_TASK_ID='run_drift_monitoring' AIRFLOW_CTX_EXECUTION_DATE='2025-07-03T00:00:00+00:00' AIRFLOW_CTX_TRY_NUMBER='2' AIRFLOW_CTX_DAG_RUN_ID='scheduled__2025-07-03T00:00:00+00:00'
[2025-07-04T14:47:58.309+0000] {taskinstance.py:430} INFO - ::endgroup::
[2025-07-04T14:47:58.323+0000] {taskinstance.py:441} INFO - ::group::Post task execution logs
[2025-07-04T14:47:58.323+0000] {taskinstance.py:2905} ERROR - Task failed with exception
Traceback (most recent call last):
  File "/home/airflow/.local/lib/python3.12/site-packages/airflow/models/taskinstance.py", line 465, in _execute_task
    result = _execute_callable(context=context, **execute_callable_kwargs)
             ^^^^^^^^^^^^^^^^^^^^^^^^^^^^^^^^^^^^^^^^^^^^^^^^^^^^^^^^^^^^^
  File "/home/airflow/.local/lib/python3.12/site-packages/airflow/models/taskinstance.py", line 432, in _execute_callable
    return execute_callable(context=context, **execute_callable_kwargs)
           ^^^^^^^^^^^^^^^^^^^^^^^^^^^^^^^^^^^^^^^^^^^^^^^^^^^^^^^^^^^^
  File "/home/airflow/.local/lib/python3.12/site-packages/airflow/models/baseoperator.py", line 400, in wrapper
    return func(self, *args, **kwargs)
           ^^^^^^^^^^^^^^^^^^^^^^^^^^^
  File "/home/airflow/.local/lib/python3.12/site-packages/airflow/operators/python.py", line 235, in execute
    return_value = self.execute_callable()
                   ^^^^^^^^^^^^^^^^^^^^^^^
  File "/home/airflow/.local/lib/python3.12/site-packages/airflow/operators/python.py", line 252, in execute_callable
    return self.python_callable(*self.op_args, **self.op_kwargs)
           ^^^^^^^^^^^^^^^^^^^^^^^^^^^^^^^^^^^^^^^^^^^^^^^^^^^^^
  File "/opt/airflow/dags/monitoring_dag.py", line 27, in run_monitoring_wrapper
    run_monitoring(reference_ts=reference_ts, current_ts=current_ts)
  File "/opt/airflow/github_pipeline/monitor.py", line 24, in run_monitoring
    raise FileNotFoundError(f"[ERROR] Reference file not found: {ref_file}")
FileNotFoundError: [ERROR] Reference file not found: data/features/actor_features_2025-07-03-15.parquet
[2025-07-04T14:47:58.331+0000] {taskinstance.py:1206} INFO - Marking task as FAILED. dag_id=daily_monitoring_dag, task_id=run_drift_monitoring, run_id=scheduled__2025-07-03T00:00:00+00:00, execution_date=20250703T000000, start_date=20250704T144758, end_date=20250704T144758
[2025-07-04T14:47:58.338+0000] {standard_task_runner.py:110} ERROR - Failed to execute job 9 for task run_drift_monitoring ([ERROR] Reference file not found: data/features/actor_features_2025-07-03-15.parquet; 391)
[2025-07-04T14:47:58.384+0000] {local_task_job_runner.py:240} INFO - Task exited with return code 1
[2025-07-04T14:47:58.397+0000] {taskinstance.py:3498} INFO - 0 downstream tasks scheduled from follow-on schedule check
[2025-07-04T14:47:58.399+0000] {local_task_job_runner.py:222} INFO - ::endgroup::
